Workbook

Sheet 0_สิ่งที่แก้ในเวอร์ชัน2
A1: PM Pricing Tool v2.1 — สรุปสิ่งที่แก้จากเวอร์ชัน 1
A2: จัดทำ 19-09-2026 | ไฟล์เดิมยังใช้งานได้ ไม่ถูกแก้ไข — ไฟล์นี้เป็นเวอร์ชันแยก
A4: 1) ข้อผิดพลาดที่แก้ / BUG FIXES
A5: หัวข้อ | B5: ปัญหาในเวอร์ชัน 1 | C5: วิธีแก้ในเวอร์ชัน 2
A6: ต้นทุนเครื่องอบไม่ถูกใช้ | B6: สูตรต้นทุนแพ็คเกจ (ชีต 2 คอลัมน์ F) ใช้ 'ต้นทุนเฉลี่ยต่อเครื่อง' 325 บาทกับทั้งเครื่องซักและเครื่องอบ ทั้งที่ไฟล์เองระบุไว้ว่าเครื่องอบหนักกว่า 1.27 เท่า (413 บาท) → GM สูงเกินจริง 4-7 จุดทุกแพ็คเกจ | C6: แยกต้นทุนเครื่องซัก/เครื่องอบเป็นสองบรรทัด และสร้าง 'ต้นทุนต่อ 1 ชุดคู่ ต่อรอบ' (ชีต 1 แถว 33) ให้ทุกสูตรดึงไปใช้จุดเดียว
A7: GM ของดีลในชีต 3 สูงเกินจริง | B7: สูตร D32 นับทุกเครื่องเป็นเครื่องซัก และไม่นับต้นทุนเดินทางส่วนเกิน ทั้งที่เก็บเงินค่าเดินทางเป็นรายได้ | C7: แยกบล็อกต้นทุนออกมา 6 บรรทัด ครบทั้งงาน PM เครื่องเดี่ยว เดินทาง ที่พัก งานซ่อมด่วน และท่อ Flex
A8: ขั้นส่วนลด 6 ชุดคู่ขึ้นไปขาดทุน | B8: ลด 25% พร้อมแถมรอบบริการฟรีอีก 1 รอบพร้อมกัน ทำให้ Care+ เหลือ 3,675 บาท เทียบต้นทุน 5 รอบ = 3,690 บาท และเวอร์ชัน 1 ไม่มีคอลัมน์ต้นทุน/GM ในตารางส่วนลดเลย จึงไม่มีอะไรเตือน | C8: เพิ่มคอลัมน์ GM ของทั้ง 3 แพ็คเกจในทุกขั้นส่วนลด พร้อมแถบสีแดงเมื่อติดลบ และคอลัมน์สถานะสรุปรายขั้น
A9: ค่าแรงซ่อมด่วนไม่มีต้นทุน | B9: Care Pro ให้ฟรีไม่จำกัด แต่ตั้งเผื่อไว้เพียง 1,000 บาทซึ่งระบุว่าเป็นค่าท่อ Flex | Care+ เก็บ 750 บาท/ครั้ง ซึ่งต่ำกว่าต้นทุนจริงต่อครั้ง | C9: เพิ่มสมมติฐาน 'ต้นทุนงานซ่อมด่วนต่อครั้ง' และ 'จำนวนครั้งเฉลี่ยต่อปี' แยกจากค่าท่อ Flex พร้อมตารางตรวจกำไรต่อครั้งของทั้ง 3 แพ็คเกจ (ชีต 2 แถว 13-15)
A10: ชีต 4 ไม่มีคอลัมน์สถานะ | B10: คู่มือในชีต 5 เขียนว่า 'คอลัมน์สถานะจะเตือนเมื่อใกล้ถึงกำหนดหรือเกินกำหนด' แต่ในไฟล์ไม่มีคอลัมน์นั้น และสูตรรอบคงเหลือไม่ได้นับรอบฟรีของลูกค้า 6 ชุดคู่ขึ้นไป | C10: เพิ่มคอลัมน์ รอบตามสัญญา / รอบ 5 (ฟรี) / วันคงเหลือ / สถานะ พร้อมแถบสีแดง-เหลือง-เขียวอัตโนมัติ
A12: 2) ความสามารถที่เพิ่มเข้ามา / NEW
A13: ราคาขั้นต่ำอัตโนมัติ | B13: เวอร์ชัน 1 บอกได้แค่ผ่าน/ไม่ผ่านเกณฑ์ | C13: ชีต 2 คอลัมน์ I และชีต 3 แถว 43 คำนวณราคาขั้นต่ำที่ยังได้ GM ตามเป้าให้ทันที (ปัดขึ้นทีละ 50/100 บาท)
A14: เพดานส่วนลดขณะต่อรอง | B14: ต้องลองปรับตัวเลขไปมาเอง | C14: ชีต 3 แถว 44 บอกเปอร์เซ็นต์ส่วนลดสูงสุดที่ให้ได้โดยไม่หลุดเป้า GM
A15: เลือกฐานต้นทุนได้ | B15: ใช้ค่าเฉลี่ยของสองกรณีเสมอ | C15: ชีต 1 แถว 23 เลือกได้ว่าจะใช้ค่าเฉลี่ย / งานกระจุกจุดเดียว / งาน Route หลายจุด — ร้านสะดวกซักที่มีหลายเครื่องในจุดเดียวควรใช้ 'งานกระจุกจุดเดียว'
A16: ตรวจ GM ของดีล 3 ปี | B16: คำนวณแค่ราคาและส่วนที่ประหยัด | C16: ชีต 3 แถว 49 แสดง GM ของดีลชำระล่วงหน้า 3 ปี พร้อมเตือนเรื่องต้นทุนที่จะขึ้นระหว่างสัญญา
A17: เลือกแพ็คเกจด้วยชื่อ | B17: ต้องพิมพ์เลข 1/2/3 | C17: ชีต 3 และชีต 4 เลือกจาก dropdown เป็นชื่อแพ็คเกจโดยตรง
A19: 3) การปรับเป้า Gross Margin ให้ตรงกับตลาด (v2.1)
A20: เดิมใช้เป้าเดียว 50% | B20: บอกได้แค่ผ่าน/ไม่ผ่าน ใช้ต่อรองจริงไม่ได้ และไม่มีแพ็กเกจไหนผ่านเลยแม้ลูกค้ารายเดียว ทำให้ทุกดีลขึ้นสถานะแดงจนคนใช้เลิกสนใจสัญญาณเตือน | C20: แยกเป็น 2 ระดับ: GM ขั้นต่ำที่ยอมรับได้ (Floor) 35% และ GM เป้าหมาย (Target) 45% สถานะจึงมี 3 ระดับ — ผ่านเป้าหมาย / รับได้ / ต่ำกว่าขั้นต่ำ
A21: ที่มาของตัวเลข 35-45% | B21: ต้องมีหลักฐานอ้างอิง ไม่ใช่ตั้งลอยๆ | C21: ราคาตลาด CODE CLEAN 600 บาท/เครื่อง/ครั้ง = 1,200 บาท/ชุดคู่/รอบ เทียบต้นทุนของเราต่อชุดคู่ ให้ GM ประมาณ 38% (ดูแถวล่างสุดของชีต 1) จึงตั้ง Floor ต่ำกว่าเล็กน้อยที่ 35% และ Target สูงกว่าตลาดพอสมควรที่ 45%
A22: เพิ่มราคา 2 ระดับทุกที่ | B22: เวอร์ชัน 2.0 มีแค่ราคาขั้นต่ำเดียว | C22: ชีต 2 มีทั้ง 'ราคาขั้นต่ำ (Floor)' และ 'ราคาเป้าหมาย (Target)' | ชีต 3 บอกทั้งราคาที่ควรยื่นก่อนต่อรอง และเพดานล่างสุดที่ห้ามต่ำกว่า
A23: เพดานส่วนลดต่อแพ็กเกจ | B23: ตอบลูกค้าไม่ได้ทันทีว่าลดได้กี่เปอร์เซ็นต์ | C23: ชีต 2 เพิ่มตาราง 'เพดานส่วนลดที่ยังผ่าน GM ขั้นต่ำ' ทั้งกรณีมีและไม่มีรอบบริการฟรี
A24: บันไดส่วนลดที่แนะนำ | B24: บันไดเดิม 10/20/25% + รอบฟรี ทำให้ขาดทุนตั้งแต่ขั้น 2 เป็นต้นไป | C24: เสนอบันไดใหม่ 0 / 5 / 10 / 12% และตัดรอบบริการฟรีออกทั้งหมด พร้อมตาราง GM ให้เทียบกับบันไดเดิมแบบเคียงข้างกัน
A26: 4) สิ่งที่ยังต้องตัดสินใจ / TO DECIDE
A27: ขั้นส่วนลด 6 ชุดคู่ขึ้นไป | B27: ยังติดลบอยู่ตามตัวเลขปัจจุบัน | C27: ทางเลือก: (ก) ตัดรอบบริการฟรีออก (ข) ลดส่วนลดเหลือ 15% (ค) ขึ้นราคาป้าย Care+ — แก้ได้ที่ชีต 2 ตารางแถว 24-29
A28: ฐานต้นทุนที่ใช้กับลูกค้ารายใหญ่ | B28: ตั้งไว้ที่ 'ค่าเฉลี่ย' ซึ่งเป็นค่ากลางระหว่างงานกระจุกกับงาน Route | C28: ร้านสะดวกซักที่มีเครื่อง 8-10 ตัวในจุดเดียวควรใช้ฐาน 'งานกระจุกจุดเดียว' (ต้นทุนชุดคู่ 681 แทน 738) ซึ่งทำให้ลดราคาได้มากขึ้นอย่างมีเหตุผล — ชีต 3 มีบรรทัดแนะนำให้อัตโนมัติตามจำนวนเครื่องที่กรอก
A29: จำนวนครั้งซ่อมด่วนเฉลี่ย | B29: ตั้งไว้ 2 ครั้ง/ปี/ชุดคู่ เป็นค่าประมาณ | C29: เก็บสถิติจริงจากงานที่ผ่านมา แล้วแก้ที่ชีต 1 แถว 20 — ตัวเลขนี้กระทบ GM ของ Care Pro มากที่สุด

Sheet 1_สมมติฐานต้นทุน
A1: สมมติฐานต้นทุนงาน PM — แก้ตัวเลขในช่องสีเหลืองเท่านั้น
A2: ช่องสีเหลือง = ช่องกรอกข้อมูล (ตัวอักษรสีน้ำเงิน) | ช่องอื่นเป็นสูตรคำนวณ ห้ามแก้
A4: รายการ | B4: ค่า | C4: หน่วย | D4: หมายเหตุ / ที่มาของตัวเลข
A5: ค่าแรงช่างหลัก ต่อวัน | B5: 900 | C5: บาท/วัน | D5: ตัวเลขจากผู้ใช้ — ปรับตามค่าจ้างจริงในพื้นที่
A6: ค่าแรงผู้ช่วยช่าง ต่อวัน | B6: 600 | C6: บาท/วัน | D6: ตัวเลขจากผู้ใช้
A7: ค่ารถ + น้ำมัน + ทางด่วน ต่อวัน | B7: 500 | C7: บาท/วัน | D7: ตัวเลขจากผู้ใช้ — งานในเขตเมือง
A8: วัสดุสิ้นเปลือง ต่อเครื่อง | B8: 100 | C8: บาท/เครื่อง | D8: น้ำยาล้าง ผ้า จารบี ซิลิโคน เทป foil ถุงมือ
A9: จำนวนเครื่องที่ทำได้ ต่อวัน (งานกระจุกจุดเดียว) | B9: 10 | C9: เครื่อง/วัน | D9: เครื่องซัก 45-60 นาที / เครื่องอบ 60-75 นาที
A10: จำนวนเครื่องที่ทำได้ ต่อวัน (งาน Route หลายจุด) | B10: 8 | C10: เครื่อง/วัน | D10: เสียเวลาเดินทางระหว่างจุด
A11: ค่าเดินทางส่วนเกิน (ราคาที่เรียกเก็บ) | B11: 12 | C11: บาท/กม. | D11: คิดเฉพาะขาไป | เบนช์มาร์กตลาด SPINZ = 10 บาท/กม.
A12: ค่าที่พักกรณีค้างคืน | B12: 1200 | C12: บาท/คืน/ทีม | D12: ตัวเลขจากผู้ใช้
A13: ค่าเดินทางเสียเที่ยว (ลูกค้าไม่พร้อมให้เข้างาน) | B13: 800 | C13: บาท/ครั้ง | D13: ตามเงื่อนไขในใบเสนอราคาข้อ 5
A14: ★ ★ GM ขั้นต่ำที่ยอมรับได้ (Floor) | B14: 0.35 | C14: % | D14: ต่ำกว่านี้ไม่ควรรับงาน หรือต้องขออนุมัติพิเศษ — อ้างอิงราคาตลาด CODE CLEAN 600 บาท/เครื่อง/ครั้ง ซึ่งให้ GM ราว 38% บนโครงสร้างต้นทุนชุดนี้ (ดูแถวล่างสุดของชีต)
A15: ★ ★ GM เป้าหมายที่ต้องการ (Target) | B15: 0.45 | C15: % | D15: ระดับที่ราคาป้ายควรอยู่ เพื่อเหลือรองรับ overhead และกำไร — เดิมตั้งไว้ 50% ซึ่งสูงกว่าที่ตลาดจ่ายจริง
A17: ★ สมมติฐานที่เพิ่มในเวอร์ชัน 2 — จำเป็นต่อการคิดต้นทุนให้ครบ
A18: ★ ตัวคูณต้นทุนเครื่องอบ (เทียบเครื่องซัก) | B18: 1.27 | C18: เท่า | D18: เดิมค่านี้ถูกฝังไว้ในสูตร F12 เท่านั้น ทำให้ต้นทุนแพ็กเกจคิดเครื่องอบเท่าเครื่องซัก — งานอบหนักกว่าเพราะต้องถอดล้างท่อลมร้อนและตรวจระบบแก๊ส
A19: ★ ต้นทุนงานซ่อมด่วน (Corrective) ต่อครั้ง | B19: 800 | C19: บาท/ครั้ง | D19: ประมาณ 1/3 วันทำงาน + วัสดุ — ใช้คิดต้นทุนของ Care Pro ที่ให้ฟรีไม่จำกัด
A20: ★ จำนวนครั้ง Corrective เฉลี่ย ต่อปี ต่อชุดคู่ | B20: 2 | C20: ครั้ง/ปี | D20: ปรับตามสถิติจริง — ตัวเลขนี้คือความเสี่ยงหลักของแพ็กเกจ Care Pro
A21: ★ ต้นทุนท่อ Flex ลมร้อน 4 นิ้ว ต่อเส้น | B21: 600 | C21: บาท/เส้น | D21: Care Pro ให้ฟรีปีละ 1 เส้นต่อเครื่องอบ 1 เครื่อง
A22: ★ ต้นทุนเดินทางส่วนเกินจริง | B22: 8 | C22: บาท/กม. | D22: ค่าน้ำมัน + สึกหรอจริง — เดิมไม่ถูกนับเป็นต้นทุนในชีต 3 ทำให้ GM สูงเกินจริง
A23: ★ ฐานต้นทุนที่ใช้ตั้งราคา | B23: ค่าเฉลี่ย (แนะนำ) | C23: เลือก | D23: งานกระจุกจุดเดียว = ร้านสะดวกซักที่มีเครื่องหลายตัวในจุดเดียว | Route = งานกระจายหลายจุด
A25: ต้นทุนที่คำนวณได้ / Calculated cost
A26: รายการ | B26: ค่า | C26: หน่วย | D26: สูตร
A27: ต้นทุนค่าแรง+รถ ต่อวัน | B27: =$B$5+$B$6+$B$7 -> 2000 | C27: บาท/วัน | D27: ช่างหลัก + ผู้ช่วย + ค่ารถ
A28: ต้นทุนต่อเครื่อง — งานกระจุกจุดเดียว | B28: =ROUND($B$27/$B$9+$B$8,0) -> 300 | C28: บาท/เครื่อง | D28: ต้นทุนต่อวัน ÷ เครื่องต่อวัน + วัสดุ
A29: ต้นทุนต่อเครื่อง — งาน Route หลายจุด | B29: =ROUND($B$27/$B$10+$B$8,0) -> 350 | C29: บาท/เครื่อง | D29: ต้นทุนต่อวัน ÷ เครื่องต่อวัน + วัสดุ
A30: ต้นทุนเฉลี่ยของสองกรณี | B30: =ROUND(AVERAGE($B$28,$B$29),0) -> 325 | C30: บาท/เครื่อง | D30: ค่าเฉลี่ย
A31: ต้นทุนต่อเครื่องซัก (ที่ใช้ตั้งราคา) | B31: =IF($B$23="งานกระจุกจุดเดียว",$B$28,IF($B$23="งาน Route หลายจุด",$B$29,$B$30)) -> 325 | C31: บาท/เครื่อง/รอบ | D31: ตามฐานต้นทุนที่เลือกไว้ด้านบน
A32: ★ ต้นทุนต่อเครื่องอบ (ที่ใช้ตั้งราคา) | B32: =ROUND($B$31*$B$18,0) -> 413 | C32: บาท/เครื่อง/รอบ | D32: ต้นทุนเครื่องซัก x ตัวคูณเครื่องอบ
A33: ★ ต้นทุนต่อ 1 ชุดคู่ ต่อรอบ PM | B33: =$B$31+$B$32 -> 738 | C33: บาท/ชุดคู่/รอบ | D33: ตัวเลขหลักที่ชีต 2 และ 3 ใช้คิดต้นทุนทั้งหมด
A35: ราคาตลาดอ้างอิง (เก็บไว้เทียบ ไม่เชื่อมกับสูตร)
A36: ผู้ให้บริการ | B36: ราคา | C36: หน่วย | D36: ที่มา
A37: CODE CLEAN — PM ตามรอบ | B37: 600 | C37: บาท/เครื่อง/ครั้ง | D37: code-clean.com/services/preventive-maintenance (ขั้นต่ำ 4,800 บาท/ครั้ง)
A38: CODE CLEAN — ซ่อมเมื่อเสีย เครื่องแรก | B38: 1500 | C38: บาท/ครั้ง | D38: ไม่รวมอะไหล่
A39: CODE CLEAN — ซ่อมเมื่อเสีย เครื่องที่ 2 ขึ้นไป | B39: 1000 | C39: บาท/ครั้ง | D39: ไม่รวมอะไหล่
A40: CODE CLEAN — ค่าเดินทางส่วนเกิน | B40: 10 | C40: บาท/กม. | D40: ฟรี 50 กม.แรก คิดเฉพาะขาไป จาก hub 4 จังหวัด
A42: ข้อควรระวัง: ราคาตลาดอ้างอิงเป็นข้อมูล ณ วันที่จัดทำ ควรตรวจสอบใหม่ก่อนใช้อ้างอิงกับลูกค้า
A44: ★ GM ที่ได้ถ้าตั้งราคาเท่าราคาตลาด (CODE CLEAN) | B44: =IFERROR((B37*2-$B$33)/(B37*2),0) -> 0.385 | C44: % | D44: ราคาตลาด 600 บาท/เครื่อง/ครั้ง = 1,200 บาท/ชุดคู่/รอบ เทียบต้นทุนต่อชุดคู่ของเรา — ใช้เป็นหลักฐานว่าเป้า GM ที่ตั้งไว้สมเหตุสมผลกับตลาดหรือไม่

Sheet 2_ราคาแพ็คเกจ
A1: โครงสร้างราคาแพ็คเกจ และการตรวจสอบ Gross Margin
A2: แก้ราคาขายในคอลัมน์ B (สีเหลือง) แล้วดู GM ในคอลัมน์ G — คอลัมน์ I บอกราคาขั้นต่ำที่ยังได้ GM ตามเป้า
A4: แพ็คเกจ (ต่อ 1 ชุดคู่ ต่อปี) | B4: ราคาขาย/ปี | C4: รอบ PM/ปี | D4: ต้นทุนงาน PM | E4: ★ ต้นทุนบริการที่แถมฟรี | F4: ต้นทุนรวม | G4: Gross Margin | H4: สถานะเทียบเป้า | I4: ★ ราคาขั้นต่ำ (Floor) | J4: ★ ราคาเป้าหมาย (Target) | K4: หมายเหตุ
A5: Care — 2 รอบ/ปี | B5: 2600 | C5: 2 | D5: =C5*1_สมมติฐานต้นทุน!$B$33 -> 1476 | E5: =0 -> 0 | F5: =D5+E5 -> 1476 | G5: =IFERROR((B5-F5)/B5,0) -> 0.43230769 | H5: =IF(G5>=1_สมมติฐานต้นทุน!$B$15,"ผ่านเป้าหมาย",IF(G5>=1_สมมติฐานต้นทุน!$B$14,"รับได้ (ต่ำกว่าเป้า "&TEXT(1_สมมติฐานต้นทุน!$B$15-G5,"0.0%")&")","ต่ำกว่าขั้นต่ำ — ทบทวนราคา")) -> รับได้ (ต่ำกว่าเป้า 1.8%) | I5: =IFERROR(CEILING(F5/(1-1_สมมติฐานต้นทุน!$B$14),50),0) -> 2300 | J5: =IFERROR(CEILING(F5/(1-1_สมมติฐานต้นทุน!$B$15),50),0) -> 2700 | K5: PM ทุก 6 เดือน · ถอดล้างท่อลมร้อนปีละ 1 · ตอบสนอง 72 ชม. · ค่าแรงซ่อมด่วนเก็บ 1,500/ครั้ง
A6: Care+ — 4 รอบ/ปี | B6: 4900 | C6: 4 | D6: =C6*1_สมมติฐานต้นทุน!$B$33 -> 2952 | E6: =0 -> 0 | F6: =D6+E6 -> 2952 | G6: =IFERROR((B6-F6)/B6,0) -> 0.39755102 | H6: =IF(G6>=1_สมมติฐานต้นทุน!$B$15,"ผ่านเป้าหมาย",IF(G6>=1_สมมติฐานต้นทุน!$B$14,"รับได้ (ต่ำกว่าเป้า "&TEXT(1_สมมติฐานต้นทุน!$B$15-G6,"0.0%")&")","ต่ำกว่าขั้นต่ำ — ทบทวนราคา")) -> รับได้ (ต่ำกว่าเป้า 5.2%) | I6: =IFERROR(CEILING(F6/(1-1_สมมติฐานต้นทุน!$B$14),50),0) -> 4550 | J6: =IFERROR(CEILING(F6/(1-1_สมมติฐานต้นทุน!$B$15),50),0) -> 5400 | K6: PM ทุก 3 เดือน · ถอดล้างท่อปีละ 2 · ตอบสนอง 48 ชม. · ค่าแรงซ่อมด่วนลด 50% เหลือ 750/ครั้ง
A7: Care Pro — 4 รอบ/ปี | B7: 7900 | C7: 4 | D7: =C7*1_สมมติฐานต้นทุน!$B$33 -> 2952 | E7: =1_สมมติฐานต้นทุน!$B$21+1_สมมติฐานต้นทุน!$B$20*1_สมมติฐานต้นทุน!$B$19 -> 2200 | F7: =D7+E7 -> 5152 | G7: =IFERROR((B7-F7)/B7,0) -> 0.3478481 | H7: =IF(G7>=1_สมมติฐานต้นทุน!$B$15,"ผ่านเป้าหมาย",IF(G7>=1_สมมติฐานต้นทุน!$B$14,"รับได้ (ต่ำกว่าเป้า "&TEXT(1_สมมติฐานต้นทุน!$B$15-G7,"0.0%")&")","ต่ำกว่าขั้นต่ำ — ทบทวนราคา")) -> ต่ำกว่าขั้นต่ำ — ทบทวนราคา | I7: =IFERROR(CEILING(F7/(1-1_สมมติฐานต้นทุน!$B$14),50),0) -> 7950 | J7: =IFERROR(CEILING(F7/(1-1_สมมติฐานต้นทุน!$B$15),50),0) -> 9400 | K7: ตอบสนอง 24 ชม. · ถอดล้างทุกรอบ · ★ ฟรีค่าแรงซ่อมไม่จำกัด + ท่อ Flex ปีละ 1 เส้น = ต้นทุนแฝงที่ต้องตั้งเผื่อ
A9: ราคาขั้นต่ำปัดขึ้นทีละ 50 บาท | ต้นทุนงาน PM = รอบต่อปี x ต้นทุนต่อชุดคู่ต่อรอบ (ชีต 1 แถว 33)
A11: ★ ตรวจสอบงานซ่อมด่วน (Corrective) — คิดแยกจากแพ็คเกจ
A12: รายการ | B12: เรียกเก็บ/ครั้ง | C12: ต้นทุน/ครั้ง | D12: กำไร/ครั้ง | E12: GM | J12: หมายเหตุ
A13: Care — เก็บเต็ม | B13: 1500 | C13: =1_สมมติฐานต้นทุน!$B$19 -> 800 | D13: =B13-C13 -> 700 | E13: =IFERROR(D13/B13,-1) -> 0.46666667 | J13: ราคาตามใบเสนอราคา
A14: Care+ — ลด 50% | B14: 750 | C14: =1_สมมติฐานต้นทุน!$B$19 -> 800 | D14: =B14-C14 -> -50 | E14: =IFERROR(D14/B14,-1) -> -0.066666667 | J14: ★ ราคาลด 50% ต่ำกว่าต้นทุนต่อครั้ง — ยิ่งลูกค้าเรียกมาก ยิ่งขาดทุน
A15: Care Pro — ฟรีไม่จำกัด | B15: 0 | C15: =1_สมมติฐานต้นทุน!$B$19 -> 800 | D15: =B15-C15 -> -800 | E15: =IFERROR(D15/B15,-1) -> -1 | J15: ต้นทุนถูกตั้งเผื่อไว้ในคอลัมน์ E ของตารางด้านบนแล้ว
A17: ราคางาน PM แบบครั้งเดียว (Single PM)
A18: รายการ | B18: ราคาขาย | D18: ต้นทุน | G18: Gross Margin | H18: สถานะ | I18: ราคาขั้นต่ำ | J18: หมายเหตุ
A19: เครื่องซัก 18 kg | B19: 650 | D19: =1_สมมติฐานต้นทุน!$B$31 -> 325 | G19: =IFERROR((B19-D19)/B19,0) -> 0.5 | H19: =IF(G19>=1_สมมติฐานต้นทุน!$B$15,"ผ่านเป้าหมาย",IF(G19>=1_สมมติฐานต้นทุน!$B$14,"รับได้","ต่ำกว่าขั้นต่ำ")) -> ผ่านเป้าหมาย | I19: =IFERROR(CEILING(D19/(1-1_สมมติฐานต้นทุน!$B$14),50),0) -> 500 | J19: =IFERROR(CEILING(D19/(1-1_สมมติฐานต้นทุน!$B$15),50),0) -> 600 | K19: งานมาตรฐาน
A20: เครื่องอบ 14 kg | B20: 850 | D20: =1_สมมติฐานต้นทุน!$B$32 -> 413 | G20: =IFERROR((B20-D20)/B20,0) -> 0.51411765 | H20: =IF(G20>=1_สมมติฐานต้นทุน!$B$15,"ผ่านเป้าหมาย",IF(G20>=1_สมมติฐานต้นทุน!$B$14,"รับได้","ต่ำกว่าขั้นต่ำ")) -> ผ่านเป้าหมาย | I20: =IFERROR(CEILING(D20/(1-1_สมมติฐานต้นทุน!$B$14),50),0) -> 650 | J20: =IFERROR(CEILING(D20/(1-1_สมมติฐานต้นทุน!$B$15),50),0) -> 800 | K20: หนักกว่าเพราะต้องถอดล้างท่อลมร้อนและตรวจระบบแก๊ส
A22: ★ ส่วนลดตามจำนวนชุดคู่ — พร้อมต้นทุนและ GM ของทุกขั้น (เวอร์ชัน 1 ไม่มีการตรวจส่วนนี้)
A23: จำนวนชุดคู่ | B23: ส่วนลด | C23: รอบฟรีเพิ่ม | D23: Care ราคา/ชุด | E23: Care GM | F23: Care+ ราคา/ชุด | G23: Care+ GM | H23: Care Pro ราคา/ชุด | I23: Care Pro GM | J23: สถานะขั้นนี้
A24: 1 | B24: 0 | C24: 0 | D24: =ROUND($B$5*(1-$B24),0) -> 2600 | E24: =IFERROR((D24-(($C$5+$C24)*1_สมมติฐานต้นทุน!$B$33+$E$5))/D24,0) -> 0.43230769 | F24: =ROUND($B$6*(1-$B24),0) -> 4900 | G24: =IFERROR((F24-(($C$6+$C24)*1_สมมติฐานต้นทุน!$B$33+$E$6))/F24,0) -> 0.39755102 | H24: =ROUND($B$7*(1-$B24),0) -> 7900 | I24: =IFERROR((H24-(($C$7+$C24)*1_สมมติฐานต้นทุน!$B$33+$E$7))/H24,0) -> 0.3478481 | J24: =IF(MIN(E24,G24,I24)<0,"ขาดทุน — ต้องแก้ทันที",IF(MIN(E24,G24,I24)<1_สมมติฐานต้นทุน!$B$14,"ต่ำกว่าขั้นต่ำ",IF(MIN(E24,G24,I24)<1_สมมติฐานต้นทุน!$B$15,"รับได้","ผ่านเป้าหมายทุกแพ็คเกจ"))) -> ต่ำกว่าขั้นต่ำ
A25: 2 | B25: 0.1 | C25: 0 | D25: =ROUND($B$5*(1-$B25),0) -> 2340 | E25: =IFERROR((D25-(($C$5+$C25)*1_สมมติฐานต้นทุน!$B$33+$E$5))/D25,0) -> 0.36923077 | F25: =ROUND($B$6*(1-$B25),0) -> 4410 | G25: =IFERROR((F25-(($C$6+$C25)*1_สมมติฐานต้นทุน!$B$33+$E$6))/F25,0) -> 0.33061224 | H25: =ROUND($B$7*(1-$B25),0) -> 7110 | I25: =IFERROR((H25-(($C$7+$C25)*1_สมมติฐานต้นทุน!$B$33+$E$7))/H25,0) -> 0.27538678 | J25: =IF(MIN(E25,G25,I25)<0,"ขาดทุน — ต้องแก้ทันที",IF(MIN(E25,G25,I25)<1_สมมติฐานต้นทุน!$B$14,"ต่ำกว่าขั้นต่ำ",IF(MIN(E25,G25,I25)<1_สมมติฐานต้นทุน!$B$15,"รับได้","ผ่านเป้าหมายทุกแพ็คเกจ"))) -> ต่ำกว่าขั้นต่ำ
A26: 3 | B26: 0.1 | C26: 0 | D26: =ROUND($B$5*(1-$B26),0) -> 2340 | E26: =IFERROR((D26-(($C$5+$C26)*1_สมมติฐานต้นทุน!$B$33+$E$5))/D26,0) -> 0.36923077 | F26: =ROUND($B$6*(1-$B26),0) -> 4410 | G26: =IFERROR((F26-(($C$6+$C26)*1_สมมติฐานต้นทุน!$B$33+$E$6))/F26,0) -> 0.33061224 | H26: =ROUND($B$7*(1-$B26),0) -> 7110 | I26: =IFERROR((H26-(($C$7+$C26)*1_สมมติฐานต้นทุน!$B$33+$E$7))/H26,0) -> 0.27538678 | J26: =IF(MIN(E26,G26,I26)<0,"ขาดทุน — ต้องแก้ทันที",IF(MIN(E26,G26,I26)<1_สมมติฐานต้นทุน!$B$14,"ต่ำกว่าขั้นต่ำ",IF(MIN(E26,G26,I26)<1_สมมติฐานต้นทุน!$B$15,"รับได้","ผ่านเป้าหมายทุกแพ็คเกจ"))) -> ต่ำกว่าขั้นต่ำ
A27: 4 | B27: 0.2 | C27: 0 | D27: =ROUND($B$5*(1-$B27),0) -> 2080 | E27: =IFERROR((D27-(($C$5+$C27)*1_สมมติฐานต้นทุน!$B$33+$E$5))/D27,0) -> 0.29038462 | F27: =ROUND($B$6*(1-$B27),0) -> 3920 | G27: =IFERROR((F27-(($C$6+$C27)*1_สมมติฐานต้นทุน!$B$33+$E$6))/F27,0) -> 0.24693878 | H27: =ROUND($B$7*(1-$B27),0) -> 6320 | I27: =IFERROR((H27-(($C$7+$C27)*1_สมมติฐานต้นทุน!$B$33+$E$7))/H27,0) -> 0.18481013 | J27: =IF(MIN(E27,G27,I27)<0,"ขาดทุน — ต้องแก้ทันที",IF(MIN(E27,G27,I27)<1_สมมติฐานต้นทุน!$B$14,"ต่ำกว่าขั้นต่ำ",IF(MIN(E27,G27,I27)<1_สมมติฐานต้นทุน!$B$15,"รับได้","ผ่านเป้าหมายทุกแพ็คเกจ"))) -> ต่ำกว่าขั้นต่ำ
A28: 5 | B28: 0.2 | C28: 0 | D28: =ROUND($B$5*(1-$B28),0) -> 2080 | E28: =IFERROR((D28-(($C$5+$C28)*1_สมมติฐานต้นทุน!$B$33+$E$5))/D28,0) -> 0.29038462 | F28: =ROUND($B$6*(1-$B28),0) -> 3920 | G28: =IFERROR((F28-(($C$6+$C28)*1_สมมติฐานต้นทุน!$B$33+$E$6))/F28,0) -> 0.24693878 | H28: =ROUND($B$7*(1-$B28),0) -> 6320 | I28: =IFERROR((H28-(($C$7+$C28)*1_สมมติฐานต้นทุน!$B$33+$E$7))/H28,0) -> 0.18481013 | J28: =IF(MIN(E28,G28,I28)<0,"ขาดทุน — ต้องแก้ทันที",IF(MIN(E28,G28,I28)<1_สมมติฐานต้นทุน!$B$14,"ต่ำกว่าขั้นต่ำ",IF(MIN(E28,G28,I28)<1_สมมติฐานต้นทุน!$B$15,"รับได้","ผ่านเป้าหมายทุกแพ็คเกจ"))) -> ต่ำกว่าขั้นต่ำ
A29: 6 | B29: 0.25 | C29: 1 | D29: =ROUND($B$5*(1-$B29),0) -> 1950 | E29: =IFERROR((D29-(($C$5+$C29)*1_สมมติฐานต้นทุน!$B$33+$E$5))/D29,0) -> -0.13538462 | F29: =ROUND($B$6*(1-$B29),0) -> 3675 | G29: =IFERROR((F29-(($C$6+$C29)*1_สมมติฐานต้นทุน!$B$33+$E$6))/F29,0) -> -0.0040816327 | H29: =ROUND($B$7*(1-$B29),0) -> 5925 | I29: =IFERROR((H29-(($C$7+$C29)*1_สมมติฐานต้นทุน!$B$33+$E$7))/H29,0) -> 0.005907173 | J29: =IF(MIN(E29,G29,I29)<0,"ขาดทุน — ต้องแก้ทันที",IF(MIN(E29,G29,I29)<1_สมมติฐานต้นทุน!$B$14,"ต่ำกว่าขั้นต่ำ",IF(MIN(E29,G29,I29)<1_สมมติฐานต้นทุน!$B$15,"รับได้","ผ่านเป้าหมายทุกแพ็คเกจ"))) -> ขาดทุน — ต้องแก้ทันที
A30: หมายเหตุ: ขั้น 6 ชุดคู่ขึ้นไปในเงื่อนไขเดิมให้ทั้งส่วนลด 25% และรอบบริการฟรีอีก 1 รอบพร้อมกัน ซึ่งเป็นจุดที่ GM ติดลบ — ทางเลือกคือตัดรอบฟรีออก หรือลดส่วนลดเหลือ 15%
A32: ★ เพดานส่วนลดที่ยังผ่าน GM ขั้นต่ำ — ใช้ตอบทันทีเวลาลูกค้าขอลดราคา
A33: แพ็คเกจ | B33: ราคาป้าย | C33: ต้นทุน (รอบปกติ) | D33: เพดานส่วนลด | E33: ต้นทุน (+รอบฟรี 1 รอบ) | F33: เพดานส่วนลดถ้าแถมรอบฟรี | K33: หมายเหตุ
A34: =LEFT($A$5,FIND(" —",$A$5)-1) -> Care | B34: =$B$5 -> 2600 | C34: =$F$5 -> 1476 | D34: =IFERROR(MAX(0,1-(C34/(1-1_สมมติฐานต้นทุน!$B$14))/B34),0) -> 0.12662722 | E34: =$C$5*1_สมมติฐานต้นทุน!$B$33+1_สมมติฐานต้นทุน!$B$33+$E$5 -> 2214 | F34: =IFERROR(MAX(0,1-(E34/(1-1_สมมติฐานต้นทุน!$B$14))/B34),0) -> 0 | K34: 0% = ลดไม่ได้เลยที่ GM ขั้นต่ำปัจจุบัน
A35: =LEFT($A$6,FIND(" —",$A$6)-1) -> Care+ | B35: =$B$6 -> 4900 | C35: =$F$6 -> 2952 | D35: =IFERROR(MAX(0,1-(C35/(1-1_สมมติฐานต้นทุน!$B$14))/B35),0) -> 0.073155416 | E35: =$C$6*1_สมมติฐานต้นทุน!$B$33+1_สมมติฐานต้นทุน!$B$33+$E$6 -> 3690 | F35: =IFERROR(MAX(0,1-(E35/(1-1_สมมติฐานต้นทุน!$B$14))/B35),0) -> 0 | K35: 0% = ลดไม่ได้เลยที่ GM ขั้นต่ำปัจจุบัน
A36: =LEFT($A$7,FIND(" —",$A$7)-1) -> Care Pro | B36: =$B$7 -> 7900 | C36: =$F$7 -> 5152 | D36: =IFERROR(MAX(0,1-(C36/(1-1_สมมติฐานต้นทุน!$B$14))/B36),0) -> 0 | E36: =$C$7*1_สมมติฐานต้นทุน!$B$33+1_สมมติฐานต้นทุน!$B$33+$E$7 -> 5890 | F36: =IFERROR(MAX(0,1-(E36/(1-1_สมมติฐานต้นทุน!$B$14))/B36),0) -> 0 | K36: 0% = ลดไม่ได้เลยที่ GM ขั้นต่ำปัจจุบัน
A37: เพดานนี้คิดจากฐานต้นทุนที่เลือกไว้ในชีต 1 — ลูกค้าหลายชุดคู่ในจุดเดียวควรเลือกฐาน 'งานกระจุกจุดเดียว' ซึ่งต้นทุนต่ำกว่า ทำให้ลดราคาได้มากขึ้นอย่างมีเหตุผล
A39: ★ บันไดส่วนลดที่แนะนำ (ทางเลือกแทนบันไดเดิมที่ทำให้ขาดทุน)
A40: จำนวนชุดคู่ | B40: ส่วนลดที่แนะนำ | C40: รอบฟรีเพิ่ม | D40: Care GM | E40: Care+ GM | F40: Care Pro GM | K40: สถานะ
A41: 1 | B41: 0 | C41: 0 | D41: =IFERROR((ROUND($B$5*(1-$B41),0)-(($C$5+$C41)*1_สมมติฐานต้นทุน!$B$33+$E$5))/ROUND($B$5*(1-$B41),0),0) -> 0.43230769 | E41: =IFERROR((ROUND($B$6*(1-$B41),0)-(($C$6+$C41)*1_สมมติฐานต้นทุน!$B$33+$E$6))/ROUND($B$6*(1-$B41),0),0) -> 0.39755102 | F41: =IFERROR((ROUND($B$7*(1-$B41),0)-(($C$7+$C41)*1_สมมติฐานต้นทุน!$B$33+$E$7))/ROUND($B$7*(1-$B41),0),0) -> 0.3478481 | K41: =IF(MIN(D41,E41,F41)>=1_สมมติฐานต้นทุน!$B$14,"ผ่านขั้นต่ำทุกแพ็คเกจ",IF(MIN(D41,E41)>=1_สมมติฐานต้นทุน!$B$14,"Care/Care+ ผ่าน · Care Pro ต่ำกว่าขั้นต่ำตั้งแต่ราคาป้าย","ยังต่ำกว่าขั้นต่ำ")) -> Care/Care+ ผ่าน · Care Pro ต่ำกว่าขั้นต่ำตั้งแต่ราคาป้าย
A42: 2-3 | B42: 0.05 | C42: 0 | D42: =IFERROR((ROUND($B$5*(1-$B42),0)-(($C$5+$C42)*1_สมมติฐานต้นทุน!$B$33+$E$5))/ROUND($B$5*(1-$B42),0),0) -> 0.40242915 | E42: =IFERROR((ROUND($B$6*(1-$B42),0)-(($C$6+$C42)*1_สมมติฐานต้นทุน!$B$33+$E$6))/ROUND($B$6*(1-$B42),0),0) -> 0.36584318 | F42: =IFERROR((ROUND($B$7*(1-$B42),0)-(($C$7+$C42)*1_สมมติฐานต้นทุน!$B$33+$E$7))/ROUND($B$7*(1-$B42),0),0) -> 0.31352432 | K42: =IF(MIN(D42,E42,F42)>=1_สมมติฐานต้นทุน!$B$14,"ผ่านขั้นต่ำทุกแพ็คเกจ",IF(MIN(D42,E42)>=1_สมมติฐานต้นทุน!$B$14,"Care/Care+ ผ่าน · Care Pro ต่ำกว่าขั้นต่ำตั้งแต่ราคาป้าย","ยังต่ำกว่าขั้นต่ำ")) -> Care/Care+ ผ่าน · Care Pro ต่ำกว่าขั้นต่ำตั้งแต่ราคาป้าย
A43: 4-5 | B43: 0.1 | C43: 0 | D43: =IFERROR((ROUND($B$5*(1-$B43),0)-(($C$5+$C43)*1_สมมติฐานต้นทุน!$B$33+$E$5))/ROUND($B$5*(1-$B43),0),0) -> 0.36923077 | E43: =IFERROR((ROUND($B$6*(1-$B43),0)-(($C$6+$C43)*1_สมมติฐานต้นทุน!$B$33+$E$6))/ROUND($B$6*(1-$B43),0),0) -> 0.33061224 | F43: =IFERROR((ROUND($B$7*(1-$B43),0)-(($C$7+$C43)*1_สมมติฐานต้นทุน!$B$33+$E$7))/ROUND($B$7*(1-$B43),0),0) -> 0.27538678 | K43: =IF(MIN(D43,E43,F43)>=1_สมมติฐานต้นทุน!$B$14,"ผ่านขั้นต่ำทุกแพ็คเกจ",IF(MIN(D43,E43)>=1_สมมติฐานต้นทุน!$B$14,"Care/Care+ ผ่าน · Care Pro ต่ำกว่าขั้นต่ำตั้งแต่ราคาป้าย","ยังต่ำกว่าขั้นต่ำ")) -> ยังต่ำกว่าขั้นต่ำ
A44: 6 ขึ้นไป | B44: 0.12 | C44: 0 | D44: =IFERROR((ROUND($B$5*(1-$B44),0)-(($C$5+$C44)*1_สมมติฐานต้นทุน!$B$33+$E$5))/ROUND($B$5*(1-$B44),0),0) -> 0.3548951 | E44: =IFERROR((ROUND($B$6*(1-$B44),0)-(($C$6+$C44)*1_สมมติฐานต้นทุน!$B$33+$E$6))/ROUND($B$6*(1-$B44),0),0) -> 0.31539889 | F44: =IFERROR((ROUND($B$7*(1-$B44),0)-(($C$7+$C44)*1_สมมติฐานต้นทุน!$B$33+$E$7))/ROUND($B$7*(1-$B44),0),0) -> 0.2589183 | K44: =IF(MIN(D44,E44,F44)>=1_สมมติฐานต้นทุน!$B$14,"ผ่านขั้นต่ำทุกแพ็คเกจ",IF(MIN(D44,E44)>=1_สมมติฐานต้นทุน!$B$14,"Care/Care+ ผ่าน · Care Pro ต่ำกว่าขั้นต่ำตั้งแต่ราคาป้าย","ยังต่ำกว่าขั้นต่ำ")) -> ยังต่ำกว่าขั้นต่ำ
A45: ข้อเสนอนี้ตัดรอบบริการฟรีออกทั้งหมด และจำกัดส่วนลดสูงสุดที่ 12% — ถ้าต้องการให้ของแถมกับลูกค้ารายใหญ่ ควรเป็นสิ่งที่ต้นทุนต่ำ เช่น ยกระดับเวลาตอบสนอง หรือฟรี Single PM ให้เครื่องเสริม แทนการเพิ่มรอบ PM ซึ่งเป็นต้นทุนเต็มจำนวน
A46: ตัวเลข GM ด้านบนคิดบนฐานต้นทุนที่เลือกไว้ในชีต 1 — ถ้าเปลี่ยนเป็นฐาน 'งานกระจุกจุดเดียว' (ซึ่งตรงกับลักษณะงานร้านสะดวกซักที่มีเครื่องหลายตัวในจุดเดียว) ทุกขั้นของบันไดนี้จะผ่าน GM ขั้นต่ำ สำหรับ Care และ Care+

Sheet 3_คำนวณใบเสนอราคา
A1: ตัวคำนวณใบเสนอราคา PM รายลูกค้า
A2: กรอกเฉพาะช่องสีเหลือง — ผลลัพธ์ด้านล่างนำไปกรอกในใบเสนอราคา PDF ได้ทันที
A3: ข้อมูลนำเข้า
A4: ชื่อลูกค้า / อาคาร | B4: ลูกค้าตัวอย่าง
A5: จำนวนชุดคู่ (ซัก+อบ) | B5: 2
A6: จำนวนเครื่องซักเดี่ยว (ไม่จับคู่) | B6: 0
A7: จำนวนเครื่องอบเดี่ยว (ไม่จับคู่) | B7: 0
A8: แพ็คเกจที่เลือก | B8: Care+ | E8: เลือกจากรายการ
A9: ระยะทางจากฐานทีมช่าง (กม.) | B9: 45 | E9: ฟรีในรัศมี 30 กม.
A10: จำนวนคืนที่ต้องค้างแรม | B10: 0
A11: อยู่ในรอบ Route ประจำโซน? | B11: ไม่ใช่ | E11: ถ้าใช่ = ยกเว้นค่าเดินทางส่วนเกิน
A12: ชำระล่วงหน้า 3 ปี? | B12: ไม่ใช่ | E12: ลด 15% ตามข้อ 5.2 ของสัญญา
A13: ★ จำนวนครั้งเรียกซ่อมด่วนที่คาดว่าจะเกิด/ปี | B13: 2 | E13: ใช้คิดทั้งรายได้ (Care/Care+) และต้นทุน (ทุกแพ็คเกจ)
A15: รายได้ของดีลนี้ (ต่อปี)
A16: รายการ | B16: จำนวน | C16: ราคา/หน่วย | D16: จำนวนเงิน | E16: หมายเหตุ
A17: ค่าบริการรายปี — ชุดคู่ | B17: =$B$5 -> 2 | C17: =INDEX(2_ราคาแพ็คเกจ!$B$5:$B$7,IFERROR(MATCH($B$8,Z_LISTS!$B$2:$B$4,0),2)) -> 4900 | D17: =B17*C17 -> 9800 | E17: ราคาต่อชุดคู่ต่อปี ดึงจากชีต 2 ตามแพ็คเกจที่เลือก
A18: ค่าบริการรายปี — เครื่องซักเดี่ยว | B18: =$B$6 -> 0 | C18: =2_ราคาแพ็คเกจ!$B$19*INDEX(2_ราคาแพ็คเกจ!$C$5:$C$7,IFERROR(MATCH($B$8,Z_LISTS!$B$2:$B$4,0),2)) -> 2600 | D18: =B18*C18 -> 0 | E18: ราคา Single PM เครื่องซัก x จำนวนรอบต่อปี
A19: ค่าบริการรายปี — เครื่องอบเดี่ยว | B19: =$B$7 -> 0 | C19: =2_ราคาแพ็คเกจ!$B$20*INDEX(2_ราคาแพ็คเกจ!$C$5:$C$7,IFERROR(MATCH($B$8,Z_LISTS!$B$2:$B$4,0),2)) -> 3400 | D19: =B19*C19 -> 0 | E19: ราคา Single PM เครื่องอบ x จำนวนรอบต่อปี
A20: รวมค่าบริการก่อนส่วนลด | D20: =SUM(D17:D19) -> 9800
A21: ส่วนลดตามจำนวนชุดคู่ | C21: =INDEX(2_ราคาแพ็คเกจ!$B$24:$B$29,IFERROR(MATCH(MIN(MAX($B$5,1),6),2_ราคาแพ็คเกจ!$A$24:$A$29,0),1)) -> 0.1 | D21: =-ROUND(D20*C21,0) -> -980 | E21: ดึงอัตราส่วนลดจากตารางขั้นบันไดในชีต 2
A22: ค่าเดินทางส่วนเกิน (เรียกเก็บ) | B22: =IF($B$11="ใช่",0,MAX(0,$B$9-30)) -> 15 | C22: =1_สมมติฐานต้นทุน!$B$11 -> 12 | D22: =ROUND(B22*C22*(INDEX(2_ราคาแพ็คเกจ!$C$5:$C$7,IFERROR(MATCH($B$8,Z_LISTS!$B$2:$B$4,0),2))+IF($B$5=0,0,INDEX(2_ราคาแพ็คเกจ!$C$24:$C$29,IFERROR(MATCH(MIN(MAX($B$5,1),6),2_ราคาแพ็คเกจ!$A$24:$A$29,0),1)))),0) -> 720 | E22: กม.ส่วนเกิน x อัตรา x จำนวนรอบ (รวมรอบฟรี)
A23: ค่าที่พักค้างคืน (เรียกเก็บ) | B23: =$B$10 -> 0 | C23: =1_สมมติฐานต้นทุน!$B$12 -> 1200 | D23: =B23*C23 -> 0
A24: ★ รายได้ค่าแรงซ่อมด่วน | B24: =$B$13 -> 2 | C24: =INDEX(2_ราคาแพ็คเกจ!$B$13:$B$15,IFERROR(MATCH($B$8,Z_LISTS!$B$2:$B$4,0),2)) -> 750 | D24: =B24*C24 -> 1500 | E24: Care เก็บ 1,500 · Care+ เก็บ 750 · Care Pro ฟรี (= 0)
A25: ราคาสุทธิก่อน VAT (ต่อปี) | D25: =D20+D21+D22+D23+D24 -> 11040
A26: ภาษีมูลค่าเพิ่ม 7% | D26: =ROUND(D25*0.07,0) -> 773
A27: รวมทั้งสิ้น (ต่อปี) | D27: =D25+D26 -> 11813 | E27: นำตัวเลขนี้ไปกรอกในใบเสนอราคา
A29: ★ ต้นทุนของดีลนี้ (ต่อปี) — เวอร์ชัน 1 คิดเฉพาะงาน PM และคิดเครื่องอบเท่าเครื่องซัก
A30: รายการ | B30: จำนวน | C30: ต้นทุน/หน่วย | D30: จำนวนเงิน | E30: หมายเหตุ
A31: ต้นทุนงาน PM — ชุดคู่ | B31: =$B$5*(INDEX(2_ราคาแพ็คเกจ!$C$5:$C$7,IFERROR(MATCH($B$8,Z_LISTS!$B$2:$B$4,0),2))+IF($B$5=0,0,INDEX(2_ราคาแพ็คเกจ!$C$24:$C$29,IFERROR(MATCH(MIN(MAX($B$5,1),6),2_ราคาแพ็คเกจ!$A$24:$A$29,0),1)))) -> 8 | C31: =1_สมมติฐานต้นทุน!$B$33 -> 738 | D31: =B31*C31 -> 5904 | E31: จำนวนชุดคู่ x (รอบตามแพ็คเกจ + รอบฟรี) x ต้นทุนต่อชุดคู่ต่อรอบ
A32: ต้นทุนงาน PM — เครื่องเดี่ยว | B32: =($B$6+$B$7)*(INDEX(2_ราคาแพ็คเกจ!$C$5:$C$7,IFERROR(MATCH($B$8,Z_LISTS!$B$2:$B$4,0),2))+IF($B$5=0,0,INDEX(2_ราคาแพ็คเกจ!$C$24:$C$29,IFERROR(MATCH(MIN(MAX($B$5,1),6),2_ราคาแพ็คเกจ!$A$24:$A$29,0),1)))) -> 0 | C32: =IFERROR(($B$6*1_สมมติฐานต้นทุน!$B$31+$B$7*1_สมมติฐานต้นทุน!$B$32)/MAX($B$6+$B$7,1),0) -> 0 | D32: =($B$6*1_สมมติฐานต้นทุน!$B$31+$B$7*1_สมมติฐานต้นทุน!$B$32)*(INDEX(2_ราคาแพ็คเกจ!$C$5:$C$7,IFERROR(MATCH($B$8,Z_LISTS!$B$2:$B$4,0),2))+IF($B$5=0,0,INDEX(2_ราคาแพ็คเกจ!$C$24:$C$29,IFERROR(MATCH(MIN(MAX($B$5,1),6),2_ราคาแพ็คเกจ!$A$24:$A$29,0),1)))) -> 0 | E32: แยกต้นทุนเครื่องซักและเครื่องอบตามจริง | รวมรอบฟรีที่แถมให้ (มีต้นทุนแต่ไม่มีรายได้)
A33: ★ ต้นทุนเดินทางส่วนเกิน (จริง) | B33: =IF($B$11="ใช่",0,MAX(0,$B$9-30)) -> 15 | C33: =1_สมมติฐานต้นทุน!$B$22 -> 8 | D33: =ROUND(B33*C33*(INDEX(2_ราคาแพ็คเกจ!$C$5:$C$7,IFERROR(MATCH($B$8,Z_LISTS!$B$2:$B$4,0),2))+IF($B$5=0,0,INDEX(2_ราคาแพ็คเกจ!$C$24:$C$29,IFERROR(MATCH(MIN(MAX($B$5,1),6),2_ราคาแพ็คเกจ!$A$24:$A$29,0),1)))),0) -> 480 | E33: ค่าน้ำมัน+สึกหรอจริง — เวอร์ชัน 1 ไม่ได้นับส่วนนี้
A34: ต้นทุนที่พักค้างคืน | B34: =$B$10 -> 0 | C34: =1_สมมติฐานต้นทุน!$B$12 -> 1200 | D34: =B34*C34 -> 0 | E34: ส่งผ่านเท่าราคาที่เรียกเก็บ
A35: ★ ต้นทุนงานซ่อมด่วน | B35: =$B$13 -> 2 | C35: =1_สมมติฐานต้นทุน!$B$19 -> 800 | D35: =B35*C35 -> 1600 | E35: เกิดทุกแพ็คเกจ — Care Pro ไม่มีรายได้มาชดเชย
A36: ★ ต้นทุนท่อ Flex (เฉพาะ Care Pro) | B36: =IF($B$8="Care Pro",$B$5,0) -> 0 | C36: =1_สมมติฐานต้นทุน!$B$21 -> 600 | D36: =B36*C36 -> 0 | E36: Care Pro ให้ฟรีปีละ 1 เส้นต่อเครื่องอบ 1 เครื่อง
A37: รวมต้นทุนทั้งหมด | D37: =SUM(D31:D36) -> 7984
A39: ผลลัพธ์และเพดานการต่อรอง
A40: กำไรขั้นต้นเป็นตัวเงิน (ต่อปี) | D40: =D25-D37 -> 3056 | E40: ราคาสุทธิก่อน VAT − ต้นทุนรวม
A41: Gross Margin ของดีลนี้ | D41: =IFERROR((D25-D37)/D25,0) -> 0.27681159
A42: สถานะเทียบเป้าหมาย | D42: =IF(D41>=1_สมมติฐานต้นทุน!$B$15,"ผ่านเป้าหมาย",IF(D41>=1_สมมติฐานต้นทุน!$B$14,"รับได้ — ต่ำกว่าเป้า "&TEXT(1_สมมติฐานต้นทุน!$B$15-D41,"0.0%"),"ต่ำกว่าขั้นต่ำ "&TEXT(1_สมมติฐานต้นทุน!$B$14-D41,"0.0%")&" — ทบทวนส่วนลดหรือปฏิเสธงาน")) -> ต่ำกว่าขั้นต่ำ 7.3% — ทบทวนส่วนลดหรือปฏิเสธงาน
A43: ★ ราคาขั้นต่ำที่ยังผ่าน GM ขั้นต่ำ (ก่อน VAT) | D43: =IFERROR(CEILING(D37/(1-1_สมมติฐานต้นทุน!$B$14),100),0) -> 12300 | E43: เพดานล่างสุดของการต่อรอง — ห้ามเสนอต่ำกว่านี้
...

Sheet 4_ทะเบียนลูกค้าและรอบPM
A1: ทะเบียนสัญญา PM และตารางติดตามรอบเข้าปฏิบัติงาน
A2: 1 บรรทัด = 1 สัญญา | กรอกวันที่เข้าจริงในคอลัมน์ J-N ระบบจะคำนวณรอบคงเหลือ วันครบกำหนดถัดไป และสถานะให้
A4: เลขที่สัญญา | B4: ชื่อลูกค้า/อาคาร | C4: จังหวัด/โซน | D4: แพ็คเกจ | E4: จำนวนชุดคู่ | F4: จำนวนเครื่อง | G4: รอบตามสัญญา | H4: วันเริ่มสัญญา | I4: วันสิ้นสุดสัญญา | J4: รอบ 1 | K4: รอบ 2 | L4: รอบ 3 | M4: รอบ 4 | N4: ★ รอบ 5 (ฟรี) | O4: รอบที่ทำแล้ว | P4: รอบคงเหลือ | Q4: กำหนดรอบถัดไป | R4: ★ วันคงเหลือ | S4: ★ สถานะ
A5: PM-2569/001 | B5: หอพักตัวอย่าง (แถวตัวอย่าง — ลบทิ้งได้) | C5: ภูเก็ต | D5: Care+ | E5: 2 | F5: =IF(E5="","",E5*2) -> 4 | G5: =IF(D5="","",IF(D5="Care",2,4)+IF(N(E5)>=6,1,0)) -> 4 | H5: 46235 | I5: =IF(H5="","",H5+364) -> 46599 | J5: 46239 | O5: =COUNT(J5:N5) -> 1 | P5: =IF(D5="","",G5-O5) -> 3 | Q5: =IF(OR(H5="",N(P5)<=0),"",IF(O5=0,H5+7,MAX(J5:N5)+IF(D5="Care",182,91))) -> 46330 | R5: =IF(Q5="","",Q5-TODAY()) -> 46 | S5: =IF(A5="","",IF(Q5="","ครบรอบตามสัญญาแล้ว",IF(R5<0,"เกินกำหนด "&ABS(R5)&" วัน",IF(R5<=14,"ใกล้ถึงกำหนด","ปกติ")))) -> ปกติ
F6: =IF(E6="","",E6*2) | G6: =IF(D6="","",IF(D6="Care",2,4)+IF(N(E6)>=6,1,0)) | I6: =IF(H6="","",H6+364) | O6: =COUNT(J6:N6) -> 0 | P6: =IF(D6="","",G6-O6) | Q6: =IF(OR(H6="",N(P6)<=0),"",IF(O6=0,H6+7,MAX(J6:N6)+IF(D6="Care",182,91))) | R6: =IF(Q6="","",Q6-TODAY()) | S6: =IF(A6="","",IF(Q6="","ครบรอบตามสัญญาแล้ว",IF(R6<0,"เกินกำหนด "&ABS(R6)&" วัน",IF(R6<=14,"ใกล้ถึงกำหนด","ปกติ"))))
F7: =IF(E7="","",E7*2) | G7: =IF(D7="","",IF(D7="Care",2,4)+IF(N(E7)>=6,1,0)) | I7: =IF(H7="","",H7+364) | O7: =COUNT(J7:N7) -> 0 | P7: =IF(D7="","",G7-O7) | Q7: =IF(OR(H7="",N(P7)<=0),"",IF(O7=0,H7+7,MAX(J7:N7)+IF(D7="Care",182,91))) | R7: =IF(Q7="","",Q7-TODAY()) | S7: =IF(A7="","",IF(Q7="","ครบรอบตามสัญญาแล้ว",IF(R7<0,"เกินกำหนด "&ABS(R7)&" วัน",IF(R7<=14,"ใกล้ถึงกำหนด","ปกติ"))))
F8: =IF(E8="","",E8*2) | G8: =IF(D8="","",IF(D8="Care",2,4)+IF(N(E8)>=6,1,0)) | I8: =IF(H8="","",H8+364) | O8: =COUNT(J8:N8) -> 0 | P8: =IF(D8="","",G8-O8) | Q8: =IF(OR(H8="",N(P8)<=0),"",IF(O8=0,H8+7,MAX(J8:N8)+IF(D8="Care",182,91))) | R8: =IF(Q8="","",Q8-TODAY()) | S8: =IF(A8="","",IF(Q8="","ครบรอบตามสัญญาแล้ว",IF(R8<0,"เกินกำหนด "&ABS(R8)&" วัน",IF(R8<=14,"ใกล้ถึงกำหนด","ปกติ"))))
F9: =IF(E9="","",E9*2) | G9: =IF(D9="","",IF(D9="Care",2,4)+IF(N(E9)>=6,1,0)) | I9: =IF(H9="","",H9+364) | O9: =COUNT(J9:N9) -> 0 | P9: =IF(D9="","",G9-O9) | Q9: =IF(OR(H9="",N(P9)<=0),"",IF(O9=0,H9+7,MAX(J9:N9)+IF(D9="Care",182,91))) | R9: =IF(Q9="","",Q9-TODAY()) | S9: =IF(A9="","",IF(Q9="","ครบรอบตามสัญญาแล้ว",IF(R9<0,"เกินกำหนด "&ABS(R9)&" วัน",IF(R9<=14,"ใกล้ถึงกำหนด","ปกติ"))))
F10: =IF(E10="","",E10*2) | G10: =IF(D10="","",IF(D10="Care",2,4)+IF(N(E10)>=6,1,0)) | I10: =IF(H10="","",H10+364) | O10: =COUNT(J10:N10) -> 0 | P10: =IF(D10="","",G10-O10) | Q10: =IF(OR(H10="",N(P10)<=0),"",IF(O10=0,H10+7,MAX(J10:N10)+IF(D10="Care",182,91))) | R10: =IF(Q10="","",Q10-TODAY()) | S10: =IF(A10="","",IF(Q10="","ครบรอบตามสัญญาแล้ว",IF(R10<0,"เกินกำหนด "&ABS(R10)&" วัน",IF(R10<=14,"ใกล้ถึงกำหนด","ปกติ"))))
F11: =IF(E11="","",E11*2) | G11: =IF(D11="","",IF(D11="Care",2,4)+IF(N(E11)>=6,1,0)) | I11: =IF(H11="","",H11+364) | O11: =COUNT(J11:N11) -> 0 | P11: =IF(D11="","",G11-O11) | Q11: =IF(OR(H11="",N(P11)<=0),"",IF(O11=0,H11+7,MAX(J11:N11)+IF(D11="Care",182,91))) | R11: =IF(Q11="","",Q11-TODAY()) | S11: =IF(A11="","",IF(Q11="","ครบรอบตามสัญญาแล้ว",IF(R11<0,"เกินกำหนด "&ABS(R11)&" วัน",IF(R11<=14,"ใกล้ถึงกำหนด","ปกติ"))))
F12: =IF(E12="","",E12*2) | G12: =IF(D12="","",IF(D12="Care",2,4)+IF(N(E12)>=6,1,0)) | I12: =IF(H12="","",H12+364) | O12: =COUNT(J12:N12) -> 0 | P12: =IF(D12="","",G12-O12) | Q12: =IF(OR(H12="",N(P12)<=0),"",IF(O12=0,H12+7,MAX(J12:N12)+IF(D12="Care",182,91))) | R12: =IF(Q12="","",Q12-TODAY()) | S12: =IF(A12="","",IF(Q12="","ครบรอบตามสัญญาแล้ว",IF(R12<0,"เกินกำหนด "&ABS(R12)&" วัน",IF(R12<=14,"ใกล้ถึงกำหนด","ปกติ"))))
F13: =IF(E13="","",E13*2) | G13: =IF(D13="","",IF(D13="Care",2,4)+IF(N(E13)>=6,1,0)) | I13: =IF(H13="","",H13+364) | O13: =COUNT(J13:N13) -> 0 | P13: =IF(D13="","",G13-O13) | Q13: =IF(OR(H13="",N(P13)<=0),"",IF(O13=0,H13+7,MAX(J13:N13)+IF(D13="Care",182,91))) | R13: =IF(Q13="","",Q13-TODAY()) | S13: =IF(A13="","",IF(Q13="","ครบรอบตามสัญญาแล้ว",IF(R13<0,"เกินกำหนด "&ABS(R13)&" วัน",IF(R13<=14,"ใกล้ถึงกำหนด","ปกติ"))))
F14: =IF(E14="","",E14*2) | G14: =IF(D14="","",IF(D14="Care",2,4)+IF(N(E14)>=6,1,0)) | I14: =IF(H14="","",H14+364) | O14: =COUNT(J14:N14) -> 0 | P14: =IF(D14="","",G14-O14) | Q14: =IF(OR(H14="",N(P14)<=0),"",IF(O14=0,H14+7,MAX(J14:N14)+IF(D14="Care",182,91))) | R14: =IF(Q14="","",Q14-TODAY()) | S14: =IF(A14="","",IF(Q14="","ครบรอบตามสัญญาแล้ว",IF(R14<0,"เกินกำหนด "&ABS(R14)&" วัน",IF(R14<=14,"ใกล้ถึงกำหนด","ปกติ"))))
F15: =IF(E15="","",E15*2) | G15: =IF(D15="","",IF(D15="Care",2,4)+IF(N(E15)>=6,1,0)) | I15: =IF(H15="","",H15+364) | O15: =COUNT(J15:N15) -> 0 | P15: =IF(D15="","",G15-O15) | Q15: =IF(OR(H15="",N(P15)<=0),"",IF(O15=0,H15+7,MAX(J15:N15)+IF(D15="Care",182,91))) | R15: =IF(Q15="","",Q15-TODAY()) | S15: =IF(A15="","",IF(Q15="","ครบรอบตามสัญญาแล้ว",IF(R15<0,"เกินกำหนด "&ABS(R15)&" วัน",IF(R15<=14,"ใกล้ถึงกำหนด","ปกติ"))))
F16: =IF(E16="","",E16*2) | G16: =IF(D16="","",IF(D16="Care",2,4)+IF(N(E16)>=6,1,0)) | I16: =IF(H16="","",H16+364) | O16: =COUNT(J16:N16) -> 0 | P16: =IF(D16="","",G16-O16) | Q16: =IF(OR(H16="",N(P16)<=0),"",IF(O16=0,H16+7,MAX(J16:N16)+IF(D16="Care",182,91))) | R16: =IF(Q16="","",Q16-TODAY()) | S16: =IF(A16="","",IF(Q16="","ครบรอบตามสัญญาแล้ว",IF(R16<0,"เกินกำหนด "&ABS(R16)&" วัน",IF(R16<=14,"ใกล้ถึงกำหนด","ปกติ"))))
F17: =IF(E17="","",E17*2) | G17: =IF(D17="","",IF(D17="Care",2,4)+IF(N(E17)>=6,1,0)) | I17: =IF(H17="","",H17+364) | O17: =COUNT(J17:N17) -> 0 | P17: =IF(D17="","",G17-O17) | Q17: =IF(OR(H17="",N(P17)<=0),"",IF(O17=0,H17+7,MAX(J17:N17)+IF(D17="Care",182,91))) | R17: =IF(Q17="","",Q17-TODAY()) | S17: =IF(A17="","",IF(Q17="","ครบรอบตามสัญญาแล้ว",IF(R17<0,"เกินกำหนด "&ABS(R17)&" วัน",IF(R17<=14,"ใกล้ถึงกำหนด","ปกติ"))))
... F44: =IF(E44="","",E44*2) | G44: =IF(D44="","",IF(D44="Care",2,4)+IF(N(E44)>=6,1,0)) | I44: =IF(H44="","",H44+364) | O44: =COUNT(J44:N44) -> 0 | P44: =IF(D44="","",G44-O44) | Q44: =IF(OR(H44="",N(P44)<=0),"",IF(O44=0,H44+7,MAX(J44:N44)+IF(D44="Care",182,91))) | R44: =IF(Q44="","",Q44-TODAY()) | S44: =IF(A44="","",IF(Q44="","ครบรอบตามสัญญาแล้ว",IF(R44<0,"เกินกำหนด "&ABS(R44)&" วัน",IF(R44<=14,"ใกล้ถึงกำหนด","ปกติ"))))

Sheet 5_วิธีใช้
A1: วิธีใช้ไฟล์นี้
A3: ชีต 1_สมมติฐานต้นทุน | B3: แก้ค่าแรงช่าง ค่ารถ วัสดุ และจำนวนเครื่องที่ทำได้ต่อวัน ให้ตรงกับทีมช่างจริง แล้วเลือกฐานต้นทุนที่ใช้ตั้งราคา ทุกชีตที่เหลือดึงต้นทุนจากที่นี่
A4: ชีต 2_ราคาแพ็คเกจ | B4: ปรับราคาขายในคอลัมน์ B แล้วดู GM ในคอลัมน์ G | คอลัมน์ I = ราคาขั้นต่ำ (Floor) คอลัมน์ J = ราคาเป้าหมาย (Target) | ด้านล่างมีตารางส่วนลดเดิม เพดานส่วนลด และบันไดส่วนลดที่แนะนำ ให้เทียบกันได้
A5: ชีต 3_คำนวณใบเสนอราคา | B5: กรอกข้อมูลลูกค้ารายราย ระบบคำนวณรายได้ ต้นทุน GM ราคาขั้นต่ำ และส่วนลดสูงสุดที่ให้ได้
A6: ชีต 4_ทะเบียนลูกค้าและรอบPM | B6: บันทึกสัญญาและวันที่เข้าปฏิบัติงานจริง คอลัมน์สถานะจะเปลี่ยนสีเมื่อใกล้ถึงกำหนดหรือเกินกำหนด
A7: สีของเซลล์ | B7: ช่องสีเหลือง + ตัวอักษรสีน้ำเงิน = ช่องที่ต้องกรอกเอง | ตัวอักษรสีดำ = สูตรคำนวณ ห้ามพิมพ์ทับ | ★ = รายการที่เพิ่ม/แก้ไขในเวอร์ชัน 2
A8: การเพิ่มบรรทัดในชีต 4 | B8: คัดลอกบรรทัดสุดท้ายลงมา เพื่อให้สูตรในคอลัมน์ F, G, I, O, P, Q, R, S ติดไปด้วย
A9: ข้อควรระวัง | B9: ราคาตลาดอ้างอิงในชีต 1 เป็นข้อมูล ณ วันที่จัดทำ ควรตรวจสอบใหม่ก่อนใช้อ้างอิงกับลูกค้า

Sheet Z_LISTS
A1: CostBasis | B1: Pack | C1: YesNo
A2: ค่าเฉลี่ย (แนะนำ) | B2: Care | C2: ใช่
A3: งานกระจุกจุดเดียว | B3: Care+ | C3: ไม่ใช่
A4: งาน Route หลายจุด | B4: Care Pro
