Workbook

Sheet 0_README
A1: การคำนวณ ROI ร้านสะดวกซัก Samsung Commercial
A2: LAUNDROMAT ROI MODEL — Version 2.0 | อัปเดต 19-09-2026 | อิงราคาและสเปกจริงจากเอกสาร Samsung Commercial Franchise
A4: 1) วิธีใช้งาน 5 ขั้นตอน / HOW TO USE
A5: ขั้นที่ 1 | B5: ชีต H_LOCATION_SCORE — ให้คะแนนทำเลก่อน ถ้าได้ NO-GO ไม่ต้องคำนวณต่อ
A6: ขั้นที่ 2 | B6: ชีต B_PACKAGES — ตรวจราคาแพ็กเกจ (S/M/L) และกรอก 'CAPEX นอกแพ็กเกจ' ที่ลูกค้าต้องเตรียมเอง พร้อมเลือกอุปกรณ์เสริมที่จะซื้อเพิ่ม
A7: ขั้นที่ 3 | B7: ชีต A_INPUT — กรอกช่องสีเหลือง: ประชากร ค่าเช่า ราคา/รอบ และเลือกระบบรับชำระเงิน
A8: ขั้นที่ 4 | B8: ชีต F_SERVICE — เทียบ 2 ทางเลือกค่าบริการระบบ (เปิดสแกน 3% vs จ่ายรายเดือน)
A9: ขั้นที่ 5 | B9: ดูผลที่ D_DASHBOARD / E_CASHFLOW → ทดสอบความเสี่ยงที่ G_SCENARIO → พิมพ์ I_PRINT_VIEW เสนอลูกค้า
A11: 2) ความหมายของสี / COLOR LEGEND
A12: พื้นเหลือง + ตัวเลขสีน้ำเงิน | B12: ช่องกรอกข้อมูล (Input) — แก้ได้เฉพาะช่องเหล่านี้
A13: ตัวเลขสีดำ | B13: สูตรคำนวณ — ห้ามพิมพ์ทับ
A14: ตัวเลขสีเขียว | B14: ลิงก์มาจากชีตอื่น — ห้ามพิมพ์ทับ
A15: พื้นฟ้าอ่อน / เขียวอ่อน | B15: ผลลัพธ์สำคัญ (KPI)
A17: 3) แผนผังชีต / SHEET MAP
A18: 0_README | B18: หน้านี้ — คู่มือ ที่มาตัวเลข ข้อควรระวัง และสิ่งที่ต้องยืนยันกับ Samsung
A19: A_INPUT | B19: ช่องกรอก 8 หมวด: โครงการ / ตลาด / แพ็กเกจ / CAPEX / การดำเนินงาน / รายได้เสริม / OPEX / การเงิน-ภาษี
A20: B_PACKAGES | B20: สเปกเครื่อง + แพ็กเกจ S/M/L/CUSTOM + CAPEX นอกแพ็กเกจ + อุปกรณ์เสริม + checklist สิ่งที่รวมในแพ็กเกจ
A21: C_CALC | B21: เครื่องคำนวณ 9 ส่วน (capacity → รอบที่ขายได้ → รายได้ → ต้นทุน → CAPEX → P&L → KPI → health check)
A22: D_DASHBOARD | B22: สรุป KPI + งบกำไรขาดทุนต่อเดือน + คำเตือนอัตโนมัติ 7 ข้อ
A23: E_CASHFLOW | B23: กระแสเงินสด 60 เดือน + NPV + IRR + คืนทุนแบบเงินสด/คิดลด + ตารางผ่อนเงินกู้
A24: F_SERVICE | B24: ประกันที่รวมในแพ็กเกจ + ค่าบำรุงรักษาหลังปีแรก + เปรียบเทียบค่าบริการระบบ 2 ทางเลือก
A25: G_SCENARIO | B25: Worst / Base / Best + ตารางความอ่อนไหว 2 ทาง (ราคา x % ลูกค้า)
A26: H_LOCATION_SCORE | B26: ให้คะแนนทำเล 12 เกณฑ์ พร้อมข้อสรุป GO / HOLD / NO-GO
A27: I_PRINT_VIEW | B27: สรุปการลงทุน A4 1 หน้า สำหรับพิมพ์เสนอลูกค้า
A28: Z_LISTS | B28: รายการตัวเลือก dropdown (ซ่อนไว้ — คลิกขวาที่แท็บ > Unhide)
A30: 4) ตัวเลขที่ยืนยันแล้วจากเอกสาร Samsung / CONFIRMED DATA
A31: ราคาแพ็กเกจ (รวม VAT) | B31: S = 3 คู่ 699,000 บาท | M = 4 คู่ 799,000 บาท | L = 5 คู่ 899,000 บาท (Best seller)
A32: สเปกเครื่อง | B32: เครื่องซัก 18 kg รอบละ 36 นาที | เครื่องอบแก๊ส 14 kg รอบละ 45 นาที | ทนทานรับ 30,000 รอบ
A33: การรับประกัน | B33: เครื่องซัก-อบ 3 ปี | กล่องหยอดเหรียญ 1 ปี | ระบบ I'M CONTROL + ค่าบริการ ฟรี 1 ปี
A34: งานบำรุงรักษาในแพ็กเกจ | B34: S-Built-in = 1 ครั้ง | M&L-Built-in = 2 ครั้ง
A35: ค่าบริการระบบ (หลังปีแรก) | B35: 100 บาท/เครื่อง/เดือน (1 Stack = 2 เครื่อง) + 700 บาท/สาขา/เดือน (สาขา 7 เครื่องขึ้นไป) + 8,000 บาท/ปี — ยกเว้นทั้งหมดถ้าเปิดสแกน PromptPay 3%
A36: ค่าธรรมเนียมชำระเงิน | B36: PromptPay 3% ของยอดสแกน (ตัดรอบ 7 วัน โอนทุกวันพุธผ่าน K BIZ) | TrueMoney 3.5% ต่อรายการ
A37: อุปกรณ์เสริม | B37: กล่องไซด์บาร์ 13,000-17,500 | iAm Control 4,990 | กล่องสแกนออนไลน์ 5,690 | เครื่องแลกเหรียญ 16,990-49,000 | ตู้จำหน่ายสินค้า 29,990-36,990
A38: สิ่งที่รวมในแพ็กเกจ | B38: งานไฟฟ้า 1 เฟส (ตู้ควบคุม + เบรกเกอร์ 63A) | ถังน้ำ 1,000 ล. + ปั๊ม 150 W | ระบบแก๊สสลับอัตโนมัติ 2 ข้าง | ท่อลมร้อน 4" | กรุผนัง ≤25 ตร.ม. | ป้ายกล่องไฟ | เครื่องแลกเหรียญ+ตู้ขายของมินิ | CCTV | โต๊ะเก้าอี้ | พัดลม | อ่างล้างมือ
A40: 5) ตัวเลขที่ยังเป็นค่าประมาณ — ต้องยืนยันก่อนใช้จริง / TO CONFIRM
A41: 1. ค่าไฟ/ค่าน้ำ/ค่าแก๊ส ต่อรอบ | B41: ใส่ไว้ที่ B_PACKAGES: ซัก 0.55 kWh + 110 ลิตร | อบ 0.35 kWh + 0.55 กก.LPG — ต้องยืนยันจากสเปกผู้ผลิตหรือวัดจากบิลจริงของสาขาที่เปิดแล้ว
A42: 2. ราคาขายต่อรอบ | B42: ตั้งไว้ซัก 50 / อบ 50 บาท ตามราคาตลาด — ต้องสำรวจราคาคู่แข่งในทำเลจริง
A43: 3. ค่าบำรุงรักษาหลังปีแรก | B43: ตั้งไว้ 3,500 บาท/ครั้ง x 2 ครั้ง/ปี ที่ชีต F_SERVICE — ยังไม่ใช่ราคาทางการ
A44: 4. CAPEX นอกแพ็กเกจ | B44: งานไฟเมน มิเตอร์ ประปา แท่นเครื่อง ฝ้า-พื้น (รวม ~178,000-238,000 บาท) — ต้องขอใบเสนอราคาจากผู้รับเหมาจริง เพราะแตกต่างกันมากตามสภาพอาคาร
A45: 5. % การใช้งาน (utilization) | B45: ตั้งไว้ 35% วันธรรมดา / 65% วันหยุด ตามฟอร์มอ้างอิงเดิม — ควร calibrate จากข้อมูล I'M CONTROL ของสาขาที่เปิดแล้ว
...

Sheet A_INPUT
A1: การคำนวณ ROI ร้านสะดวกซัก Samsung Commercial / LAUNDROMAT ROI MODEL v2.0
A2: กรอกเฉพาะช่องสีเหลือง (Input) → ผลลัพธ์อัปเดตอัตโนมัติ • ช่อง override ใส่ 0 = ใช้ค่าจากแพ็กเกจ • ราคาแพ็กเกจ Samsung เป็นราคารวม VAT และรวมงานติดตั้ง/ตกแต่งแล้ว
A4: 1) PROJECT INFO / ข้อมูลโครงการ
A5: ชื่อโครงการ / Project name | B5: Laundromat_สาขาตัวอย่าง | D5: Input | E5: ใช้แสดงบนหน้า I_PRINT_VIEW
A6: ลูกค้า / Customer | B6: K.ตัวอย่าง | D6: Input
A7: ทำเล / Location | B7: ระบุชื่อทำเล | D7: Input
A8: ประเภททำเล / Location type | B8: หน้าหอพัก/คอนโด | D8: เลือก | E8: มีผลกับสมมติฐานความถี่การใช้บริการ
A9: ผู้รับผิดชอบ / Sales owner | B9: Krittanan | D9: เลือก
A10: วันที่ / Date | B10: 46284 | D10: Input
A12: 2) MARKET SIZE & POPULATION / ขนาดตลาดและประชากร
A13: จำนวนประชากรในรัศมีบริการ (1 กม.) | B13: 3000 | D13: Input | E13: นับจากจำนวนห้องพัก x คนเฉลี่ย/ห้อง หรือข้อมูลทะเบียนราษฎร์
A14: % คาดว่าจะใช้บริการ / Capture rate | B14: 0.35 | D14: เลือก/แก้ได้ | E14: ทำเลหอพัก 30-40% | หมู่บ้านจัดสรร 15-25%
A15: จำนวนคู่แข่งในรัศมี 500 ม. | B15: 1 | D15: Input | E15: 0 = ไม่มีคู่แข่ง
A16: ตัวคูณส่วนแบ่งตลาด / Market share factor | B16: =IFERROR(1/(1+A_INPUT!$B$15*0.6),1) -> 0.625 | D16: Formula | E16: สูตร 1/(1+คู่แข่ง x 0.6) — ปรับตัวเลข 0.6 ได้ถ้ามีข้อมูลจริง
A17: จำนวนลูกค้าคาดการณ์ / Estimated customers | B17: =A_INPUT!$B$13*A_INPUT!$B$14*A_INPUT!$B$16 -> 656.25 | D17: Formula | E17: คน/เดือน
A18: ความถี่ใช้บริการ / Usage frequency | B18: 3 | D18: Input | E18: ครั้ง/คน/เดือน
A19: รอบซักต่อการมา 1 ครั้ง | B19: 1.2 | D19: Input | E19: ลูกค้าครอบครัวมักซัก 1.5-2 รอบ/ครั้ง
A20: % ที่ใช้เครื่องอบด้วย / Dryer attach rate | B20: 0.75 | D20: Input | E20: เครื่องอบแก๊ส 45 นาที — หน้าฝน/คอนโดสูงถึง 85%
A21: ความต้องการรอบซัก / Wash cycles demand | B21: =A_INPUT!$B$17*A_INPUT!$B$18*A_INPUT!$B$19 -> 2362.5 | D21: Formula | E21: รอบ/เดือน
A22: ความต้องการรอบอบ / Dry cycles demand | B22: =A_INPUT!$B$21*A_INPUT!$B$20 -> 1771.875 | D22: Formula | E22: รอบ/เดือน
A24: 3) PACKAGE & PRICING / แพ็กเกจและราคา
A25: เลือกแพ็กเกจ / Package code | B25: L | D25: เลือก | E25: S = 3 คู่ 699,000 | M = 4 คู่ 799,000 | L = 5 คู่ 899,000 (Best seller) | CUSTOM = กำหนดเองที่ B_PACKAGES
A26: รูปแบบการคิดรายได้ / Revenue model | B26: B: แยกเครื่องซัก / เครื่องอบ | D26: เลือก | E26: โหมด A = ราคาเดียวต่อรอบ (ซัก+อบ) | โหมด B = แยกราคาซัก/อบ (แนะนำ เพราะเวลารอบต่างกัน 36 vs 45 นาที)
A27: เครื่องซักตามแพ็กเกจ | B27: =INDEX(B_PACKAGES!$D$14:$G$14,MATCH(A_INPUT!$B$25,B_PACKAGES!$D$12:$G$12,0)) -> 5 | D27: จาก B_PACKAGES | E27: เครื่อง
A28: เครื่องอบตามแพ็กเกจ | B28: =INDEX(B_PACKAGES!$D$15:$G$15,MATCH(A_INPUT!$B$25,B_PACKAGES!$D$12:$G$12,0)) -> 5 | D28: จาก B_PACKAGES | E28: เครื่อง
A29: override จำนวนเครื่องซัก (0 = ใช้แพ็กเกจ) | B29: 0 | D29: Input
A30: override จำนวนเครื่องอบ (0 = ใช้แพ็กเกจ) | B30: 0 | D30: Input
A31: เครื่องซักที่ใช้จริง | B31: =IF(A_INPUT!$B$29>0,A_INPUT!$B$29,A_INPUT!$B$27) -> 5 | D31: Formula | E31: เครื่อง
A32: เครื่องอบที่ใช้จริง | B32: =IF(A_INPUT!$B$30>0,A_INPUT!$B$30,A_INPUT!$B$28) -> 5 | D32: Formula | E32: เครื่อง
A33: รวมเครื่องทั้งหมด | B33: =A_INPUT!$B$31+A_INPUT!$B$32 -> 10 | D33: Formula | E33: ใช้คิดค่าบริการรายเดือน 100 บาท/เครื่อง (1 Stack = 2 เครื่อง)
A34: ราคา/รอบ เครื่องซัก 18 kg | B34: 50 | D34: Input | E34: บาท/รอบ — ราคาตลาด 40-60 บาท
A35: ราคา/รอบ เครื่องอบ 14 kg | B35: 50 | D35: Input | E35: บาท/รอบ — อบแก๊ส 45 นาที ตลาด 40-60 บาท
A36: ราคา/รอบ รวมซัก+อบ (ใช้เฉพาะโหมด A) | B36: 100 | D36: Input | E36: บาท/รอบ
A37: เวลา/รอบซัก (0 = ใช้ค่าจาก B_PACKAGES = 36 นาที) | B37: 0 | D37: Input | E37: นาที
A38: เวลา/รอบอบ (0 = ใช้ค่าจาก B_PACKAGES = 45 นาที) | B38: 0 | D38: Input | E38: นาที
A39: เวลา/รอบ รวมซัก+อบ (ใช้เฉพาะโหมด A) | B39: 81 | D39: Input | E39: นาที (36 + 45)
A40: เวลาโหลด-ปลดผ้า + รอเครื่องว่าง | B40: 6 | D40: Input | E40: นาที/รอบ — ทำให้ capacity สมจริงขึ้น
A42: 4) CAPEX / เงินลงทุน
A43: ราคาแพ็กเกจ Franchise (รวม VAT) | B43: =INDEX(B_PACKAGES!$D$17:$G$17,MATCH(A_INPUT!$B$25,B_PACKAGES!$D$12:$G$12,0)) -> 899000 | D43: จาก B_PACKAGES | E43: รวมเครื่อง ติดตั้ง งานระบบ งานตกแต่ง อุปกรณ์แถม และระบบ 1 ปี
A44: override ราคาแพ็กเกจ (0 = ใช้ราคาตาราง) | B44: 0 | D44: Input | E44: ใส่ราคาหลังต่อรอง/ส่วนลดจริง
...

Sheet B_PACKAGES
A1: B) MACHINE & PACKAGE MASTER / ฐานข้อมูลเครื่องและแพ็กเกจ (ราคาจริง Samsung Commercial)
A2: ที่มา: เอกสาร Samsung Commercial Franchise / ตารางสรุปราคาอุปกรณ์ (ก.ย. 2026) | ราคาแพ็กเกจเป็นราคารวม VAT แล้ว | ช่องสีเหลือง = แก้ไขได้
A4: 1) MACHINE MASTER / สเปกเครื่อง Samsung Commercial
A5: รหัส / รุ่น | B5: ประเภท | C5: ความจุ (kg) | D5: เวลา/รอบ (นาที) | E5: ไฟฟ้า kWh/รอบ | F5: น้ำ ลิตร/รอบ | G5: แก๊ส LPG กก./รอบ | H5: อายุใช้งาน (รอบ)
A6: WM18 — เครื่องซัก 18 kg | B6: เครื่องซัก | C6: 18 | D6: 36 | E6: 0.55 | F6: 110 | G6: 0 | H6: 30000
A7: DR14 — เครื่องอบแก๊ส 14 kg | B7: เครื่องอบ | C7: 14 | D7: 45 | E7: 0.35 | F7: 0 | G7: 0.55 | H7: 30000
A8: เวลา/รอบ และอายุ 30,000 รอบ = ค่าจากเอกสาร Samsung | kWh, ลิตร, กก.แก๊ส ต่อรอบ = ค่าประมาณ (เครื่องอบเป็นระบบแก๊ส LPG) — ควรวัดจากบิลจริงของสาขาที่เปิดแล้ว
A10: 2) PACKAGE MASTER / แพ็กเกจ Franchise (ราคารวม VAT)
A11: รหัสคอลัมน์ต้องตรงกับตัวเลือกใน A_INPUT เป๊ะ: S = 3 คู่ | M = 4 คู่ | L = 5 คู่ (Best seller) | CUSTOM = กำหนดเอง
A12: รายการ / Item | B12: หน่วย | C12: หมายเหตุ | D12: S | E12: M | F12: L | G12: CUSTOM
A13: จำนวนคู่ (ซัก+อบ) / Pairs | B13: คู่ | C13: 1 คู่ = ซัก 1 + อบ 1 (วางซ้อน Stack) | D13: 3 | E13: 4 | F13: 5 | G13: 4
A14: เครื่องซัก 18 kg / Washers | B14: เครื่อง | D14: =D13 -> 3 | E14: =E13 -> 4 | F14: =F13 -> 5 | G14: =G13 -> 4
A15: เครื่องอบแก๊ส 14 kg / Dryers | B15: เครื่อง | D15: =D13 -> 3 | E15: =E13 -> 4 | F15: =F13 -> 5 | G15: =G13 -> 4
A16: รวมเครื่อง (ระบบนับ 1 Stack = 2 เครื่อง) | B16: เครื่อง | C16: ใช้คิดค่าบริการรายเดือน 100 บาท/เครื่อง | D16: =D14+D15 -> 6 | E16: =E14+E15 -> 8 | F16: =F14+F15 -> 10 | G16: =G14+G15 -> 8
A17: ราคาแพ็กเกจ Franchise (รวม VAT) | B17: บาท | C17: S 699,000 | M 799,000 | L 899,000 — รวมเครื่อง ติดตั้ง งานไฟ-น้ำ-แก๊ส งานตกแต่ง Built-in อุปกรณ์แถม และระบบ I'M CONTROL 1 ปี | D17: 699000 | E17: 799000 | F17: 899000 | G17: 799000
A18: งานบำรุงรักษาที่รวมในแพ็กเกจ (ปีแรก) | B18: ครั้ง/ปี | C18: S-Built-in = 1 ครั้ง | M&L-Built-in = 2 ครั้ง | D18: 1 | E18: 2 | F18: 2 | G18: 2
A19: ประกันเครื่องซัก-อบ | B19: ปี | C19: กล่องหยอดเหรียญรับประกัน 1 ปี | D19: 3 | E19: 3 | F19: 3 | G19: 3
A20: ระบบ I'M CONTROL + ค่าบริการ ฟรี | B20: ปี | C20: หลังหมดปีแรกดูชีต F_SERVICE | D20: 1 | E20: 1 | F20: 1 | G20: 1
A21: พื้นที่แนะนำ / Recommended area | B21: ตร.ม. | C21: งานกรุผนังในแพ็กเกจครอบคลุมไม่เกิน 25 ตร.ม. | D21: 30 | E21: 35 | F21: 45 | G21: 35
A22: ประชากรในรัศมี 1 กม. ที่แนะนำ | B22: คน | D22: 2500 | E22: 3500 | F22: 4500 | G22: 3500
A24: 3) CAPEX นอกแพ็กเกจ — สิ่งที่ลูกค้าต้องเตรียมเอง (หมายเหตุข้อ 2 ของเอกสาร Samsung)
A25: งานเดินสายเมนไฟฟ้า + ขอ/เพิ่มขนาดมิเตอร์ไฟฟ้า | B25: บาท | C25: ไม่รวมในแพ็กเกจ | D25: 60000 | E25: 70000 | F25: 80000 | G25: 70000
A26: มิเตอร์ประปา + งานประปาหลักก่อนถึงจุดติดตั้ง | B26: บาท | C26: ไม่รวมในแพ็กเกจ | D26: 15000 | E26: 18000 | F26: 20000 | G26: 18000
A27: แท่นวางเครื่องซัก-อบ (ฐานปูน) | B27: บาท | C27: ไม่รวมในแพ็กเกจ | D27: 25000 | E27: 30000 | F27: 35000 | G27: 30000
A28: ฝ้าอาคาร + พื้นกระเบื้อง | B28: บาท | C28: ไม่รวมในแพ็กเกจ | D28: 40000 | E28: 50000 | F28: 60000 | G28: 50000
A29: ถังแก๊ส LPG 2 ถัง + เงินมัดจำถัง | B29: บาท | C29: ระบบแก๊สสลับอัตโนมัติ 2 ข้าง | D29: 8000 | E29: 8000 | F29: 8000 | G29: 8000
A30: อินเทอร์เน็ต + ค่าติดตั้ง | B30: บาท | C30: จำเป็นสำหรับ I'M CONTROL | D30: 5000 | E30: 5000 | F30: 5000 | G30: 5000
A31: ค่าขออนุญาต / ป้าย / อื่นๆ | B31: บาท | D31: 10000 | E31: 12000 | F31: 15000 | G31: 12000
A32: ระบบน้ำร้อน STIEBEL ELTRON + เดินท่อน้ำร้อน | B32: บาท | C32: หมายเหตุข้อ 5 — ไม่รวมในแพ็กเกจ (ใส่ 0 ถ้าไม่ติดตั้ง) | D32: 0 | E32: 0 | F32: 0 | G32: 0
A33: ค่าขนส่ง + ค่าเดินทางติดตั้ง | B33: บาท | C33: หมายเหตุข้อ 1 — ตามเงื่อนไขบริษัทฯ | D33: 15000 | E33: 15000 | F33: 15000 | G33: 15000
A34: รวม CAPEX นอกแพ็กเกจ / Total prep cost | B34: บาท | D34: =SUM(D25:D33) -> 178000 | E34: =SUM(E25:E33) -> 208000 | F34: =SUM(F25:F33) -> 238000 | G34: =SUM(G25:G33) -> 208000
A36: 4) อุปกรณ์เสริมซื้อเพิ่ม / Optional add-ons (ราคาขายจริง)
A37: รายการอุปกรณ์ | B37: ราคาขาย (บาท) | C37: จำนวน | D37: รวม (บาท) | H37: หมายเหตุ / เงื่อนไข
A38: กล่องไซด์บาร์หน้าจอสั่งงาน + ชุดรับเหรียญ (1 ชิ้น) | B38: 13000 | C38: 0 | D38: =B38*C38 -> 0 | H38: คอนโทรลแบบ All-in-One + รับเหรียญ
A39: กล่องไซด์บาร์ + ชุดรับเหรียญและแบงก์ (1 ชิ้น) | B39: 15000 | C39: 0 | D39: =B39*C39 -> 0 | H39: รับเหรียญและแบงก์
A40: กล่องไซด์บาร์ + ชุดรับเหรียญ (สำหรับ Stack บน-ล่าง) | B40: 15500 | C40: 0 | D40: =B40*C40 -> 0 | H40: สำหรับเครื่องวางซ้อน
A41: กล่องไซด์บาร์ + ชุดรับเหรียญและแบงก์ (Stack บน-ล่าง) | B41: 17500 | C41: 0 | D41: =B41*C41 -> 0 | H41: สำหรับเครื่องวางซ้อน
A42: เชื่อมต่อระบบสแกน & ระบบปฏิบัติการ iAm Control | B42: 4990 | C42: 0 | D42: =B42*C42 -> 0 | H42: ต้องมีกล่องไซด์บาร์แล้ว (ต้นทุนคู่ค้า 3,990)
A43: กล่องสแกนออนไลน์สำหรับอุปกรณ์หยอดเหรียญ | B43: 5690 | C43: 0 | D43: =B43*C43 -> 0 | H43: ติดตั้งกับอุปกรณ์หยอดเหรียญภายในร้าน
A44: เครื่องแลกเหรียญ รุ่นมินิ | B44: 16990 | C44: 0 | D44: =B44*C44 -> 0 | H44: แพ็กเกจ Franchise แถมมาแล้ว 1 เครื่อง
...

Sheet C_CALC
A1: C) CALCULATION ENGINE / เครื่องคำนวณ (ห้ามแก้ไข — เป็นสูตรทั้งหมด)
A3: 1) CAPACITY / กำลังผลิต
A4: เครื่องซักที่ใช้จริง | B4: =A_INPUT!$B$31 -> 5 | D4: จาก A_INPUT | E4: เครื่อง
A5: เครื่องอบที่ใช้จริง | B5: =A_INPUT!$B$32 -> 5 | D5: จาก A_INPUT | E5: เครื่อง
A6: รวมเครื่องซัก+อบ | B6: =A_INPUT!$B$33 -> 10 | D6: จาก A_INPUT | E6: เครื่อง
A7: เวลา/รอบซักที่ใช้ | B7: =IF(A_INPUT!$B$37>0,A_INPUT!$B$37,B_PACKAGES!$D$6) -> 36 | D7: นาที
A8: เวลา/รอบอบที่ใช้ | B8: =IF(A_INPUT!$B$38>0,A_INPUT!$B$38,B_PACKAGES!$D$7) -> 45 | D8: นาที
A9: รอบ/วัน ต่อเครื่องซัก | B9: =IFERROR(A_INPUT!$B$55*60/(C_CALC!$B$7+A_INPUT!$B$40),0) -> 34.285714 | D9: รอบ | E9: สูตร: ชั่วโมงเปิด x 60 / (เวลารอบ + เวลาโหลด-ปลดผ้า)
A10: รอบ/วัน ต่อเครื่องอบ | B10: =IFERROR(A_INPUT!$B$55*60/(C_CALC!$B$8+A_INPUT!$B$40),0) -> 28.235294 | D10: รอบ | E10: เครื่องอบ 45 นาที = คอขวดของร้าน
A11: รอบ/วัน ต่อ 1 คู่ (โหมด A) | B11: =IFERROR(A_INPUT!$B$55*60/(A_INPUT!$B$39+A_INPUT!$B$40),0) -> 16.551724 | D11: รอบ
A12: วันทำการถ่วงน้ำหนักการใช้งาน | B12: =A_INPUT!$B$58*A_INPUT!$B$56+A_INPUT!$B$59*A_INPUT!$B$57 -> 12.9 | D12: วัน-เทียบเท่า | E12: สูตร: วันธรรมดา x %ใช้งาน + วันหยุด x %ใช้งาน
A13: กำลังผลิตเครื่องซัก | B13: =C_CALC!$B$4*C_CALC!$B$9*C_CALC!$B$12 -> 2211.4286 | D13: รอบ/เดือน
A14: กำลังผลิตเครื่องอบ | B14: =C_CALC!$B$5*C_CALC!$B$10*C_CALC!$B$12 -> 1821.1765 | D14: รอบ/เดือน
A15: กำลังผลิตรวม (โหมด A) | B15: =C_CALC!$B$4*C_CALC!$B$11*C_CALC!$B$12 -> 1067.5862 | D15: รอบ/เดือน | E15: โหมด A: 1 รอบ = ใช้เครื่องซัก 1 + เครื่องอบ 1 จึงจำกัดด้วยจำนวนคู่
A16: กำลังผลิตที่ใช้ตามโหมด | B16: =IF(LEFT(A_INPUT!$B$26,1)="A",C_CALC!$B$15,C_CALC!$B$13+C_CALC!$B$14) -> 4032.605 | D16: รอบ/เดือน
A17: กำลังผลิตสูงสุด 100% | B17: =IF(LEFT(A_INPUT!$B$26,1)="A",C_CALC!$B$4*C_CALC!$B$11*A_INPUT!$B$60,(C_CALC!$B$4*C_CALC!$B$9+C_CALC!$B$5*C_CALC!$B$10)*A_INPUT!$B$60) -> 9378.1513 | D17: รอบ/เดือน | E17: เพดานถ้าเครื่องเดินเต็ม 24 ชม. ทุกวัน
A19: 2) PRICE / ราคาต่อรอบ
A20: ราคา/รอบซัก | B20: =A_INPUT!$B$34 -> 50 | D20: บาท
A21: ราคา/รอบอบ | B21: =A_INPUT!$B$35 -> 50 | D21: บาท
A22: ราคา/รอบ รวม (โหมด A) | B22: =A_INPUT!$B$36 -> 100 | D22: บาท
A24: 3) DEMAND & BILLED CYCLES / ความต้องการและรอบที่ขายได้
A25: รอบซักจาก O2O | B25: =IF(LEFT(A_INPUT!$B$61,1)="Y",A_INPUT!$B$62*A_INPUT!$B$60,0) -> 0 | D25: รอบ/เดือน
A26: รอบอบจาก O2O | B26: =IF(LEFT(A_INPUT!$B$61,1)="Y",A_INPUT!$B$62*A_INPUT!$B$60*MAX(A_INPUT!$B$63-1,0),0) -> 0 | D26: รอบ/เดือน
A27: ความต้องการรวม | B27: =IF(LEFT(A_INPUT!$B$26,1)="A",A_INPUT!$B$21+C_CALC!$B$25,A_INPUT!$B$21+A_INPUT!$B$22+C_CALC!$B$25+C_CALC!$B$26) -> 4134.375 | D27: รอบ/เดือน
A28: Capacity check (ความต้องการ / กำลังผลิต) | B28: =IFERROR(C_CALC!$B$27/C_CALC!$B$16,0) -> 1.0252368 | D28: % | E28: >100% = เครื่องไม่พอ ควรอัปแพ็กเกจหรือขึ้นราคา | <50% = ลงทุนเกินตัว
A29: อัตราที่รองรับได้จริง / Fill rate | B29: =IFERROR(MIN(1,C_CALC!$B$16/C_CALC!$B$27),1) -> 0.97538444 | D29: % | E29: ถ้าความต้องการเกินกำลังผลิต รายได้จะถูกจำกัดตามสัดส่วนนี้
A30: รอบซักที่ขายได้ (walk-in) | B30: =A_INPUT!$B$21*C_CALC!$B$29 -> 2304.3457 | D30: รอบ/เดือน
A31: รอบอบที่ขายได้ (walk-in) | B31: =IF(LEFT(A_INPUT!$B$26,1)="A",0,A_INPUT!$B$22*C_CALC!$B$29) -> 1728.2593 | D31: รอบ/เดือน
A32: รอบที่ขายได้รวม (รวม O2O) | B32: =C_CALC!$B$30+C_CALC!$B$31+(C_CALC!$B$25+C_CALC!$B$26)*C_CALC!$B$29 -> 4032.605 | D32: รอบ/เดือน
A33: จำนวนรอบที่เครื่องซักเดินจริง | B33: =C_CALC!$B$30+C_CALC!$B$25*C_CALC!$B$29 -> 2304.3457 | D33: รอบ/เดือน | E33: ใช้คิดค่าไฟ-ค่าน้ำ และอายุเครื่องตามจำนวนรอบ
A34: จำนวนรอบที่เครื่องอบเดินจริง | B34: =IF(LEFT(A_INPUT!$B$26,1)="A",C_CALC!$B$30+C_CALC!$B$25*C_CALC!$B$29,C_CALC!$B$31+C_CALC!$B$26*C_CALC!$B$29) -> 1728.2593 | D34: รอบ/เดือน | E34: โหมด A: 1 รอบรวม = เดินเครื่องอบ 1 รอบด้วย
A35: รอบเฉลี่ยต่อวัน | B35: =IFERROR(C_CALC!$B$32/A_INPUT!$B$60,0) -> 134.42017 | D35: รอบ/วัน
A37: 4) REVENUE / รายได้ต่อเดือน
A38: รายได้เครื่องซัก | B38: =IF(LEFT(A_INPUT!$B$26,1)="A",C_CALC!$B$30*C_CALC!$B$22,C_CALC!$B$30*C_CALC!$B$20) -> 115217.29 | D38: บาท
A39: รายได้เครื่องอบ | B39: =C_CALC!$B$31*C_CALC!$B$21 -> 86412.965 | D39: บาท
A40: รายได้ O2O | B40: =IF(LEFT(A_INPUT!$B$61,1)="Y",A_INPUT!$B$62*A_INPUT!$B$60*A_INPUT!$B$64*C_CALC!$B$29,0) -> 0 | D40: บาท
A41: รายได้ตู้จำหน่ายสินค้า | B41: =A_INPUT!$B$17*A_INPUT!$B$69*A_INPUT!$B$70*C_CALC!$B$29 -> 4000.6002 | D41: บาท
A42: รายได้อื่น | B42: =A_INPUT!$B$72 -> 0 | D42: บาท
A43: รายได้รวม / TOTAL REVENUE | B43: =SUM(C_CALC!$B$38,C_CALC!$B$39,C_CALC!$B$40,C_CALC!$B$41,C_CALC!$B$42) -> 205630.85 | D43: บาท/เดือน
A44: รายได้ต่อเครื่องต่อวัน | B44: =IFERROR((C_CALC!$B$38+C_CALC!$B$39)/C_CALC!$B$6/A_INPUT!$B$60,0) -> 672.10084 | D44: บาท | E44: ตัวชี้วัดเทียบสาขา: ต่ำกว่า 200 บาท/เครื่อง/วัน ถือว่าน่ากังวล
...

Sheet D_DASHBOARD
A1: D) DASHBOARD / สรุปผลการลงทุน
A2: ="โครงการ: "&A_INPUT!$B$5&" | ลูกค้า: "&A_INPUT!$B$6&" | ทำเล: "&A_INPUT!$B$7&" | แพ็กเกจ: "&A_INPUT!$B$25&" | ผู้รับผิดชอบ: "&A_INPUT!$B$9 -> โครงการ: Laundromat_สาขาตัวอย่าง | ลูกค้า: K.ตัวอย่าง | ทำเล: ระบุชื่อทำเล | แพ็กเกจ: L | ผู้รับผิดชอบ: Krittanan
A4: KEY RESULTS / ผลลัพธ์หลัก
A5: เงินลงทุนรวม / Total CAPEX | B5: =C_CALC!$B$69 -> 1362000 | D5: รายได้ต่อเดือน / Revenue | E5: =C_CALC!$B$43 -> 205630.85 | G5: EBITDA ต่อเดือน | H5: =C_CALC!$B$78 -> 101194.89
A6: บาท | D6: บาท/เดือน | G6: บาท/เดือน
A7: กำไรสุทธิต่อเดือน / Net profit | B7: =C_CALC!$B$84 -> 68942.415 | D7: อัตรากำไรสุทธิ / Net margin | E7: =C_CALC!$B$85 -> 0.33527272 | G7: ระยะคืนทุน / Payback | H7: =C_CALC!$B$90 -> 16.222148
A8: บาท/เดือน | D8: % | G8: เดือน
A9: ROI ต่อปี | B9: =C_CALC!$B$92 -> 0.60742216 | D9: จุดคุ้มทุน / BEP | E9: =C_CALC!$B$95 -> 42.573706 | G9: Capacity check | H9: =C_CALC!$B$28 -> 1.0252368
A10: %/ปี | D10: รอบ/วัน | G10: %
A12: งบกำไรขาดทุนต่อเดือน (ปีที่ 1) / MONTHLY P&L
A13: รายการ / Item | B13: บาท/เดือน | D13: % ของยอดขาย | E13: บาท/ปี
A14: รายได้เครื่องซัก | B14: =C_CALC!$B$38 -> 115217.29 | D14: =IFERROR(B14/C_CALC!$B$43,0) -> 0.56031128 | E14: =B14*12 -> 1382607.4
A15: รายได้เครื่องอบ | B15: =C_CALC!$B$39 -> 86412.965 | D15: =IFERROR(B15/C_CALC!$B$43,0) -> 0.42023346 | E15: =B15*12 -> 1036955.6
A16: รายได้ O2O | B16: =C_CALC!$B$40 -> 0 | D16: =IFERROR(B16/C_CALC!$B$43,0) -> 0 | E16: =B16*12 -> 0
A17: รายได้ vending + อื่นๆ | B17: =C_CALC!$B$41+C_CALC!$B$42 -> 4000.6002 | D17: =IFERROR(B17/C_CALC!$B$43,0) -> 0.019455253 | E17: =B17*12 -> 48007.203
A18: รวมรายได้ / Total revenue | B18: =C_CALC!$B$43 -> 205630.85 | D18: =IFERROR(B18/C_CALC!$B$43,0) -> 1 | E18: =B18*12 -> 2467570.2
A19: ค่าไฟ + ค่าน้ำ | B19: =-C_CALC!$B$48 -> -17049.553 | D19: =IFERROR(B19/C_CALC!$B$43,0) -> -0.082913399 | E19: =B19*12 -> -204594.64
A20: ค่าแก๊ส LPG (เครื่องอบ) | B20: =-C_CALC!$B$49 -> -23763.565 | D20: =IFERROR(B20/C_CALC!$B$43,0) -> -0.1155642 | E20: =B20*12 -> -285162.79
A21: วัสดุสิ้นเปลือง | B21: =-C_CALC!$B$50 -> -10081.513 | D21: =IFERROR(B21/C_CALC!$B$43,0) -> -0.049027237 | E21: =B21*12 -> -120978.15
A22: ค่าธรรมเนียมสแกน 3% + O2O | B22: =-C_CALC!$B$52-C_CALC!$B$51 -> -3701.3553 | D22: =IFERROR(B22/C_CALC!$B$43,0) -> -0.018 | E22: =B22*12 -> -44416.264
A23: ค่าซ่อม + ค่าสิทธิ์ + ต้นทุนสินค้า | B23: =-C_CALC!$B$53-C_CALC!$B$54-C_CALC!$B$55 -> -4256.6387 | D23: =IFERROR(B23/C_CALC!$B$43,0) -> -0.020700389 | E23: =B23*12 -> -51079.664
A24: รวมต้นทุนผันแปร | B24: =-C_CALC!$B$56 -> -58852.625 | D24: =IFERROR(B24/C_CALC!$B$43,0) -> -0.28620523 | E24: =B24*12 -> -706231.5
A25: กำไรส่วนเกิน / Contribution margin | B25: =C_CALC!$B$58 -> 146778.23 | D25: =IFERROR(B25/C_CALC!$B$43,0) -> 0.71379477 | E25: =B25*12 -> 1761338.7
A26: ค่าเช่า | B26: =-A_INPUT!$B$77 -> -25000 | D26: =IFERROR(B26/C_CALC!$B$43,0) -> -0.12157709 | E26: =B26*12 -> -300000
A27: ค่าจ้างพนักงาน | B27: =-A_INPUT!$B$79 -> -12000 | D27: =IFERROR(B27/C_CALC!$B$43,0) -> -0.058357002 | E27: =B27*12 -> -144000
A28: ค่าบำรุงรักษา + ค่าบริการระบบ | B28: =-A_INPUT!$B$82-A_INPUT!$B$83 -> -583.33333 | D28: =IFERROR(B28/C_CALC!$B$43,0) -> -0.0028367987 | E28: =B28*12 -> -7000
A29: ค่าใช้จ่ายคงที่อื่นๆ | B29: =-(A_INPUT!$B$87-A_INPUT!$B$77-A_INPUT!$B$79-A_INPUT!$B$82-A_INPUT!$B$83) -> -8000 | D29: =IFERROR(B29/C_CALC!$B$43,0) -> -0.038904668 | E29: =B29*12 -> -96000
A30: รวมค่าใช้จ่ายคงที่ | B30: =-A_INPUT!$B$87 -> -45583.333 | D30: =IFERROR(B30/C_CALC!$B$43,0) -> -0.22167556 | E30: =B30*12 -> -547000
A31: EBITDA | B31: =C_CALC!$B$78 -> 101194.89 | D31: =IFERROR(B31/C_CALC!$B$43,0) -> 0.49211922 | E31: =B31*12 -> 1214338.7
A32: ค่าเสื่อมราคา | B32: =-C_CALC!$B$79 -> -15016.875 | D32: =IFERROR(B32/C_CALC!$B$43,0) -> -0.073028317 | E32: =B32*12 -> -180202.5
A33: ดอกเบี้ยจ่าย | B33: =-C_CALC!$B$81 -> 0 | D33: =IFERROR(B33/C_CALC!$B$43,0) -> 0 | E33: =B33*12 -> 0
A34: ภาษีเงินได้ | B34: =-C_CALC!$B$83 -> -17235.604 | D34: =IFERROR(B34/C_CALC!$B$43,0) -> -0.08381818 | E34: =B34*12 -> -206827.25
A35: กำไรสุทธิ / NET PROFIT | B35: =C_CALC!$B$84 -> 68942.415 | D35: =IFERROR(B35/C_CALC!$B$43,0) -> 0.33527272 | E35: =B35*12 -> 827308.98
A37: HEALTH CHECK / ตรวจสุขภาพโมเดล
A38: กำลังผลิต | B38: =C_CALC!$B$101 -> เครื่องไม่พอ — ความต้องการเกินกำลังผลิต ควรอัปแพ็กเกจหรือขึ้นราคา
A39: ค่าเช่า | B39: =C_CALC!$B$102 -> OK
A40: ค่าน้ำ-ไฟ-แก๊ส | B40: =C_CALC!$B$103 -> OK
A41: ระยะคืนทุน | B41: =C_CALC!$B$104 -> ดี: คืนทุนภายใน 24 เดือน
A42: จุดคุ้มทุน | B42: =C_CALC!$B$105 -> OK
A43: อายุเครื่อง | B43: =C_CALC!$B$106 -> เครื่องจะครบ 30,000 รอบก่อนตัดค่าเสื่อมหมด — ตั้งงบเปลี่ยนเครื่องเพิ่ม
...

Sheet E_CASHFLOW
A1: E) CASH FLOW 60 เดือน / MONTHLY CASH FLOW & IRR
A3: NPV (บาท) | B3: =U67 -> 3308196.4 | C3: IRR ต่อปี (โครงการ) | D3: =IFERROR((1+IRR(P7:P67,0.01))^12-1,"N/A") -> 1.0970667 | E3: IRR ต่อปี (เจ้าของ) | F3: =IFERROR((1+IRR(R7:R67,0.01))^12-1,"N/A") -> 1.0970667 | G3: คืนทุน (เดือน) แบบเงินสด | H3: =IF(SUM(W7:W67)=0,"เกิน 60 ด.",SUM(W7:W67)) -> 16 | I3: คืนทุน (เดือน) แบบคิดลด | J3: =IF(SUM(X7:X67)=0,"เกิน 60 ด.",SUM(X7:X67)) -> 18 | K3: กำไรสะสม 5 ปี | L3: =SUM(N7:N67) -> 4756645.2
A4: NPV คิดจาก FCF โครงการ ด้วยอัตราคิดลดใน A_INPUT | IRR เจ้าของคิดจากกระแสเงินสดหลังชำระหนี้ | ปีที่ 1 ระบบหักค่าบำรุงรักษาและค่าบริการระบบออกให้ (รวมในแพ็กเกจแล้ว) | เดือนสุดท้ายของ horizon รวมมูลค่าคงเหลือของเครื่อง + เงินประกันค่าเช่า + เงินทุนหมุนเวียนคืน
A6: เดือน | B6: ปี | C6: รายได้ | D6: ต้นทุนผันแปร | E6: ค่าใช้จ่ายคงที่ | F6: EBITDA | G6: ค่าเสื่อม | H6: เงินกู้ต้นงวด | I6: ดอกเบี้ย | J6: เงินต้น | K6: เงินกู้ปลายงวด | L6: กำไรก่อนภาษี | M6: ภาษี | N6: กำไรสุทธิ | O6: มูลค่าคงเหลือ | P6: FCF โครงการ | Q6: FCF สะสม | R6: CF เจ้าของ | S6: Discount factor | T6: DCF | U6: DCF สะสม | W6: flag คืนทุนเงินสด | X6: flag คืนทุนคิดลด
A7: 0 | B7: 0 | C7: 0 | D7: 0 | E7: 0 | F7: 0 | G7: 0 | H7: =C_CALC!$B$70 -> 0 | I7: 0 | J7: 0 | K7: =C_CALC!$B$70 -> 0 | L7: 0 | M7: 0 | N7: 0 | O7: 0 | P7: =-C_CALC!$B$69 -> -1362000 | Q7: =P7 -> -1362000 | R7: =-C_CALC!$B$71 -> -1362000 | S7: 1 | T7: =P7*S7 -> -1362000 | U7: =T7 -> -1362000
A8: 1 | B8: =ROUNDUP(A8/12,0) -> 1 | C8: =IF(A8>A_INPUT!$B$112*12,0,C_CALC!$B$43*(1+A_INPUT!$B$111)^(B8-1)) -> 205630.85 | D8: =-C8*C_CALC!$B$57 -> -58852.625 | E8: =IF(A8>A_INPUT!$B$112*12,0,-((A_INPUT!$B$87-A_INPUT!$B$77)-IF(B8=1,F_SERVICE!$B$32,0)+A_INPUT!$B$77*(1+A_INPUT!$B$78)^(B8-1))) -> -45000 | F8: =C8+D8+E8 -> 101778.23 | G8: =IF(A8>A_INPUT!$B$112*12,0,IF(A8<=A_INPUT!$B$107*12,IFERROR(C_CALC!$B$66/A_INPUT!$B$107/12,0),0)+IF(A8<=A_INPUT!$B$108*12,IFERROR(C_CALC!$B$67/A_INPUT!$B$108/12,0),0)) -> 15016.875 | H8: =K7 -> 0 | I8: =H8*A_INPUT!$B$105/12 -> 0 | J8: =IF(H8<=0,0,MIN(H8,C_CALC!$B$72-I8)) -> 0 | K8: =MAX(0,H8-J8) -> 0 | L8: =F8-G8-I8 -> 86761.352 | M8: =MAX(0,L8)*A_INPUT!$B$109 -> 17352.27 | N8: =L8-M8 -> 69409.082 | O8: =IF(A8=A_INPUT!$B$112*12,MAX(0,C_CALC!$B$66*(1-A8/12/A_INPUT!$B$107))+MAX(0,C_CALC!$B$67*(1-A8/12/A_INPUT!$B$108))+C_CALC!$B$68+A_INPUT!$B$50,0) -> 0 | P8: =F8-M8+O8 -> 84425.957 | Q8: =Q7+P8 -> -1277574 | R8: =N8+G8-J8+O8 -> 84425.957 | S8: =1/(1+A_INPUT!$B$110/12)^A8 -> 0.99173554 | T8: =P8*S8 -> 83728.222 | U8: =U7+T8 -> -1278271.8 | W8: =IF(AND(Q8>=0,Q7<0),A8,0) -> 0 | X8: =IF(AND(U8>=0,U7<0),A8,0) -> 0
A9: 2 | B9: =ROUNDUP(A9/12,0) -> 1 | C9: =IF(A9>A_INPUT!$B$112*12,0,C_CALC!$B$43*(1+A_INPUT!$B$111)^(B9-1)) -> 205630.85 | D9: =-C9*C_CALC!$B$57 -> -58852.625 | E9: =IF(A9>A_INPUT!$B$112*12,0,-((A_INPUT!$B$87-A_INPUT!$B$77)-IF(B9=1,F_SERVICE!$B$32,0)+A_INPUT!$B$77*(1+A_INPUT!$B$78)^(B9-1))) -> -45000 | F9: =C9+D9+E9 -> 101778.23 | G9: =IF(A9>A_INPUT!$B$112*12,0,IF(A9<=A_INPUT!$B$107*12,IFERROR(C_CALC!$B$66/A_INPUT!$B$107/12,0),0)+IF(A9<=A_INPUT!$B$108*12,IFERROR(C_CALC!$B$67/A_INPUT!$B$108/12,0),0)) -> 15016.875 | H9: =K8 -> 0 | I9: =H9*A_INPUT!$B$105/12 -> 0 | J9: =IF(H9<=0,0,MIN(H9,C_CALC!$B$72-I9)) -> 0 | K9: =MAX(0,H9-J9) -> 0 | L9: =F9-G9-I9 -> 86761.352 | M9: =MAX(0,L9)*A_INPUT!$B$109 -> 17352.27 | N9: =L9-M9 -> 69409.082 | O9: =IF(A9=A_INPUT!$B$112*12,MAX(0,C_CALC!$B$66*(1-A9/12/A_INPUT!$B$107))+MAX(0,C_CALC!$B$67*(1-A9/12/A_INPUT!$B$108))+C_CALC!$B$68+A_INPUT!$B$50,0) -> 0 | P9: =F9-M9+O9 -> 84425.957 | Q9: =Q8+P9 -> -1193148.1 | R9: =N9+G9-J9+O9 -> 84425.957 | S9: =1/(1+A_INPUT!$B$110/12)^A9 -> 0.98353938 | T9: =P9*S9 -> 83036.253 | U9: =U8+T9 -> -1195235.5 | W9: =IF(AND(Q9>=0,Q8<0),A9,0) -> 0 | X9: =IF(AND(U9>=0,U8<0),A9,0) -> 0
A10: 3 | B10: =ROUNDUP(A10/12,0) -> 1 | C10: =IF(A10>A_INPUT!$B$112*12,0,C_CALC!$B$43*(1+A_INPUT!$B$111)^(B10-1)) -> 205630.85 | D10: =-C10*C_CALC!$B$57 -> -58852.625 | E10: =IF(A10>A_INPUT!$B$112*12,0,-((A_INPUT!$B$87-A_INPUT!$B$77)-IF(B10=1,F_SERVICE!$B$32,0)+A_INPUT!$B$77*(1+A_INPUT!$B$78)^(B10-1))) -> -45000 | F10: =C10+D10+E10 -> 101778.23 | G10: =IF(A10>A_INPUT!$B$112*12,0,IF(A10<=A_INPUT!$B$107*12,IFERROR(C_CALC!$B$66/A_INPUT!$B$107/12,0),0)+IF(A10<=A_INPUT!$B$108*12,IFERROR(C_CALC!$B$67/A_INPUT!$B$108/12,0),0)) -> 15016.875 | H10: =K9 -> 0 | I10: =H10*A_INPUT!$B$105/12 -> 0 | J10: =IF(H10<=0,0,MIN(H10,C_CALC!$B$72-I10)) -> 0 | K10: =MAX(0,H10-J10) -> 0 | L10: =F10-G10-I10 -> 86761.352 | M10: =MAX(0,L10)*A_INPUT!$B$109 -> 17352.27 | N10: =L10-M10 -> 69409.082 | O10: =IF(A10=A_INPUT!$B$112*12,MAX(0,C_CALC!$B$66*(1-A10/12/A_INPUT!$B$107))+MAX(0,C_CALC!$B$67*(1-A10/12/A_INPUT!$B$108))+C_CALC!$B$68+A_INPUT!$B$50,0) -> 0 | P10: =F10-M10+O10 -> 84425.957 | Q10: =Q9+P10 -> -1108722.1 | R10: =N10+G10-J10+O10 -> 84425.957 | S10: =1/(1+A_INPUT!$B$110/12)^A10 -> 0.97541095 | T10: =P10*S10 -> 82350.003 | U10: =U9+T10 -> -1112885.5 | W10: =IF(AND(Q10>=0,Q9<0),A10,0) -> 0 | X10: =IF(AND(U10>=0,U9<0),A10,0) -> 0
A11: 4 | B11: =ROUNDUP(A11/12,0) -> 1 | C11: =IF(A11>A_INPUT!$B$112*12,0,C_CALC!$B$43*(1+A_INPUT!$B$111)^(B11-1)) -> 205630.85 | D11: =-C11*C_CALC!$B$57 -> -58852.625 | E11: =IF(A11>A_INPUT!$B$112*12,0,-((A_INPUT!$B$87-A_INPUT!$B$77)-IF(B11=1,F_SERVICE!$B$32,0)+A_INPUT!$B$77*(1+A_INPUT!$B$78)^(B11-1))) -> -45000 | F11: =C11+D11+E11 -> 101778.23 | G11: =IF(A11>A_INPUT!$B$112*12,0,IF(A11<=A_INPUT!$B$107*12,IFERROR(C_CALC!$B$66/A_INPUT!$B$107/12,0),0)+IF(A11<=A_INPUT!$B$108*12,IFERROR(C_CALC!$B$67/A_INPUT!$B$108/12,0),0)) -> 15016.875 | H11: =K10 -> 0 | I11: =H11*A_INPUT!$B$105/12 -> 0 | J11: =IF(H11<=0,0,MIN(H11,C_CALC!$B$72-I11)) -> 0 | K11: =MAX(0,H11-J11) -> 0 | L11: =F11-G11-I11 -> 86761.352 | M11: =MAX(0,L11)*A_INPUT!$B$109 -> 17352.27 | N11: =L11-M11 -> 69409.082 | O11: =IF(A11=A_INPUT!$B$112*12,MAX(0,C_CALC!$B$66*(1-A11/12/A_INPUT!$B$107))+MAX(0,C_CALC!$B$67*(1-A11/12/A_INPUT!$B$108))+C_CALC!$B$68+A_INPUT!$B$50,0) -> 0 | P11: =F11-M11+O11 -> 84425.957 | Q11: =Q10+P11 -> -1024296.2 | R11: =N11+G11-J11+O11 -> 84425.957 | S11: =1/(1+A_INPUT!$B$110/12)^A11 -> 0.9673497 | T11: =P11*S11 -> 81669.424 | U11: =U10+T11 -> -1031216.1 | W11: =IF(AND(Q11>=0,Q10<0),A11,0) -> 0 | X11: =IF(AND(U11>=0,U10<0),A11,0) -> 0
A12: 5 | B12: =ROUNDUP(A12/12,0) -> 1 | C12: =IF(A12>A_INPUT!$B$112*12,0,C_CALC!$B$43*(1+A_INPUT!$B$111)^(B12-1)) -> 205630.85 | D12: =-C12*C_CALC!$B$57 -> -58852.625 | E12: =IF(A12>A_INPUT!$B$112*12,0,-((A_INPUT!$B$87-A_INPUT!$B$77)-IF(B12=1,F_SERVICE!$B$32,0)+A_INPUT!$B$77*(1+A_INPUT!$B$78)^(B12-1))) -> -45000 | F12: =C12+D12+E12 -> 101778.23 | G12: =IF(A12>A_INPUT!$B$112*12,0,IF(A12<=A_INPUT!$B$107*12,IFERROR(C_CALC!$B$66/A_INPUT!$B$107/12,0),0)+IF(A12<=A_INPUT!$B$108*12,IFERROR(C_CALC!$B$67/A_INPUT!$B$108/12,0),0)) -> 15016.875 | H12: =K11 -> 0 | I12: =H12*A_INPUT!$B$105/12 -> 0 | J12: =IF(H12<=0,0,MIN(H12,C_CALC!$B$72-I12)) -> 0 | K12: =MAX(0,H12-J12) -> 0 | L12: =F12-G12-I12 -> 86761.352 | M12: =MAX(0,L12)*A_INPUT!$B$109 -> 17352.27 | N12: =L12-M12 -> 69409.082 | O12: =IF(A12=A_INPUT!$B$112*12,MAX(0,C_CALC!$B$66*(1-A12/12/A_INPUT!$B$107))+MAX(0,C_CALC!$B$67*(1-A12/12/A_INPUT!$B$108))+C_CALC!$B$68+A_INPUT!$B$50,0) -> 0 | P12: =F12-M12+O12 -> 84425.957 | Q12: =Q11+P12 -> -939870.22 | R12: =N12+G12-J12+O12 -> 84425.957 | S12: =1/(1+A_INPUT!$B$110/12)^A12 -> 0.95935508 | T12: =P12*S12 -> 80994.47 | U12: =U11+T12 -> -950221.63 | W12: =IF(AND(Q12>=0,Q11<0),A12,0) -> 0 | X12: =IF(AND(U12>=0,U11<0),A12,0) -> 0
A13: 6 | B13: =ROUNDUP(A13/12,0) -> 1 | C13: =IF(A13>A_INPUT!$B$112*12,0,C_CALC!$B$43*(1+A_INPUT!$B$111)^(B13-1)) -> 205630.85 | D13: =-C13*C_CALC!$B$57 -> -58852.625 | E13: =IF(A13>A_INPUT!$B$112*12,0,-((A_INPUT!$B$87-A_INPUT!$B$77)-IF(B13=1,F_SERVICE!$B$32,0)+A_INPUT!$B$77*(1+A_INPUT!$B$78)^(B13-1))) -> -45000 | F13: =C13+D13+E13 -> 101778.23 | G13: =IF(A13>A_INPUT!$B$112*12,0,IF(A13<=A_INPUT!$B$107*12,IFERROR(C_CALC!$B$66/A_INPUT!$B$107/12,0),0)+IF(A13<=A_INPUT!$B$108*12,IFERROR(C_CALC!$B$67/A_INPUT!$B$108/12,0),0)) -> 15016.875 | H13: =K12 -> 0 | I13: =H13*A_INPUT!$B$105/12 -> 0 | J13: =IF(H13<=0,0,MIN(H13,C_CALC!$B$72-I13)) -> 0 | K13: =MAX(0,H13-J13) -> 0 | L13: =F13-G13-I13 -> 86761.352 | M13: =MAX(0,L13)*A_INPUT!$B$109 -> 17352.27 | N13: =L13-M13 -> 69409.082 | O13: =IF(A13=A_INPUT!$B$112*12,MAX(0,C_CALC!$B$66*(1-A13/12/A_INPUT!$B$107))+MAX(0,C_CALC!$B$67*(1-A13/12/A_INPUT!$B$108))+C_CALC!$B$68+A_INPUT!$B$50,0) -> 0 | P13: =F13-M13+O13 -> 84425.957 | Q13: =Q12+P13 -> -855444.26 | R13: =N13+G13-J13+O13 -> 84425.957 | S13: =1/(1+A_INPUT!$B$110/12)^A13 -> 0.95142652 | T13: =P13*S13 -> 80325.095 | U13: =U12+T13 -> -869896.53 | W13: =IF(AND(Q13>=0,Q12<0),A13,0) -> 0 | X13: =IF(AND(U13>=0,U12<0),A13,0) -> 0
A14: 7 | B14: =ROUNDUP(A14/12,0) -> 1 | C14: =IF(A14>A_INPUT!$B$112*12,0,C_CALC!$B$43*(1+A_INPUT!$B$111)^(B14-1)) -> 205630.85 | D14: =-C14*C_CALC!$B$57 -> -58852.625 | E14: =IF(A14>A_INPUT!$B$112*12,0,-((A_INPUT!$B$87-A_INPUT!$B$77)-IF(B14=1,F_SERVICE!$B$32,0)+A_INPUT!$B$77*(1+A_INPUT!$B$78)^(B14-1))) -> -45000 | F14: =C14+D14+E14 -> 101778.23 | G14: =IF(A14>A_INPUT!$B$112*12,0,IF(A14<=A_INPUT!$B$107*12,IFERROR(C_CALC!$B$66/A_INPUT!$B$107/12,0),0)+IF(A14<=A_INPUT!$B$108*12,IFERROR(C_CALC!$B$67/A_INPUT!$B$108/12,0),0)) -> 15016.875 | H14: =K13 -> 0 | I14: =H14*A_INPUT!$B$105/12 -> 0 | J14: =IF(H14<=0,0,MIN(H14,C_CALC!$B$72-I14)) -> 0 | K14: =MAX(0,H14-J14) -> 0 | L14: =F14-G14-I14 -> 86761.352 | M14: =MAX(0,L14)*A_INPUT!$B$109 -> 17352.27 | N14: =L14-M14 -> 69409.082 | O14: =IF(A14=A_INPUT!$B$112*12,MAX(0,C_CALC!$B$66*(1-A14/12/A_INPUT!$B$107))+MAX(0,C_CALC!$B$67*(1-A14/12/A_INPUT!$B$108))+C_CALC!$B$68+A_INPUT!$B$50,0) -> 0 | P14: =F14-M14+O14 -> 84425.957 | Q14: =Q13+P14 -> -771018.3 | R14: =N14+G14-J14+O14 -> 84425.957 | S14: =1/(1+A_INPUT!$B$110/12)^A14 -> 0.94356349 | T14: =P14*S14 -> 79661.251 | U14: =U13+T14 -> -790235.28 | W14: =IF(AND(Q14>=0,Q13<0),A14,0) -> 0 | X14: =IF(AND(U14>=0,U13<0),A14,0) -> 0
A15: 8 | B15: =ROUNDUP(A15/12,0) -> 1 | C15: =IF(A15>A_INPUT!$B$112*12,0,C_CALC!$B$43*(1+A_INPUT!$B$111)^(B15-1)) -> 205630.85 | D15: =-C15*C_CALC!$B$57 -> -58852.625 | E15: =IF(A15>A_INPUT!$B$112*12,0,-((A_INPUT!$B$87-A_INPUT!$B$77)-IF(B15=1,F_SERVICE!$B$32,0)+A_INPUT!$B$77*(1+A_INPUT!$B$78)^(B15-1))) -> -45000 | F15: =C15+D15+E15 -> 101778.23 | G15: =IF(A15>A_INPUT!$B$112*12,0,IF(A15<=A_INPUT!$B$107*12,IFERROR(C_CALC!$B$66/A_INPUT!$B$107/12,0),0)+IF(A15<=A_INPUT!$B$108*12,IFERROR(C_CALC!$B$67/A_INPUT!$B$108/12,0),0)) -> 15016.875 | H15: =K14 -> 0 | I15: =H15*A_INPUT!$B$105/12 -> 0 | J15: =IF(H15<=0,0,MIN(H15,C_CALC!$B$72-I15)) -> 0 | K15: =MAX(0,H15-J15) -> 0 | L15: =F15-G15-I15 -> 86761.352 | M15: =MAX(0,L15)*A_INPUT!$B$109 -> 17352.27 | N15: =L15-M15 -> 69409.082 | O15: =IF(A15=A_INPUT!$B$112*12,MAX(0,C_CALC!$B$66*(1-A15/12/A_INPUT!$B$107))+MAX(0,C_CALC!$B$67*(1-A15/12/A_INPUT!$B$108))+C_CALC!$B$68+A_INPUT!$B$50,0) -> 0 | P15: =F15-M15+O15 -> 84425.957 | Q15: =Q14+P15 -> -686592.34 | R15: =N15+G15-J15+O15 -> 84425.957 | S15: =1/(1+A_INPUT!$B$110/12)^A15 -> 0.93576545 | T15: =P15*S15 -> 79002.893 | U15: =U14+T15 -> -711232.39 | W15: =IF(AND(Q15>=0,Q14<0),A15,0) -> 0 | X15: =IF(AND(U15>=0,U14<0),A15,0) -> 0
A16: 9 | B16: =ROUNDUP(A16/12,0) -> 1 | C16: =IF(A16>A_INPUT!$B$112*12,0,C_CALC!$B$43*(1+A_INPUT!$B$111)^(B16-1)) -> 205630.85 | D16: =-C16*C_CALC!$B$57 -> -58852.625 | E16: =IF(A16>A_INPUT!$B$112*12,0,-((A_INPUT!$B$87-A_INPUT!$B$77)-IF(B16=1,F_SERVICE!$B$32,0)+A_INPUT!$B$77*(1+A_INPUT!$B$78)^(B16-1))) -> -45000 | F16: =C16+D16+E16 -> 101778.23 | G16: =IF(A16>A_INPUT!$B$112*12,0,IF(A16<=A_INPUT!$B$107*12,IFERROR(C_CALC!$B$66/A_INPUT!$B$107/12,0),0)+IF(A16<=A_INPUT!$B$108*12,IFERROR(C_CALC!$B$67/A_INPUT!$B$108/12,0),0)) -> 15016.875 | H16: =K15 -> 0 | I16: =H16*A_INPUT!$B$105/12 -> 0 | J16: =IF(H16<=0,0,MIN(H16,C_CALC!$B$72-I16)) -> 0 | K16: =MAX(0,H16-J16) -> 0 | L16: =F16-G16-I16 -> 86761.352 | M16: =MAX(0,L16)*A_INPUT!$B$109 -> 17352.27 | N16: =L16-M16 -> 69409.082 | O16: =IF(A16=A_INPUT!$B$112*12,MAX(0,C_CALC!$B$66*(1-A16/12/A_INPUT!$B$107))+MAX(0,C_CALC!$B$67*(1-A16/12/A_INPUT!$B$108))+C_CALC!$B$68+A_INPUT!$B$50,0) -> 0 | P16: =F16-M16+O16 -> 84425.957 | Q16: =Q15+P16 -> -602166.39 | R16: =N16+G16-J16+O16 -> 84425.957 | S16: =1/(1+A_INPUT!$B$110/12)^A16 -> 0.92803185 | T16: =P16*S16 -> 78349.977 | U16: =U15+T16 -> -632882.41 | W16: =IF(AND(Q16>=0,Q15<0),A16,0) -> 0 | X16: =IF(AND(U16>=0,U15<0),A16,0) -> 0
A17: 10 | B17: =ROUNDUP(A17/12,0) -> 1 | C17: =IF(A17>A_INPUT!$B$112*12,0,C_CALC!$B$43*(1+A_INPUT!$B$111)^(B17-1)) -> 205630.85 | D17: =-C17*C_CALC!$B$57 -> -58852.625 | E17: =IF(A17>A_INPUT!$B$112*12,0,-((A_INPUT!$B$87-A_INPUT!$B$77)-IF(B17=1,F_SERVICE!$B$32,0)+A_INPUT!$B$77*(1+A_INPUT!$B$78)^(B17-1))) -> -45000 | F17: =C17+D17+E17 -> 101778.23 | G17: =IF(A17>A_INPUT!$B$112*12,0,IF(A17<=A_INPUT!$B$107*12,IFERROR(C_CALC!$B$66/A_INPUT!$B$107/12,0),0)+IF(A17<=A_INPUT!$B$108*12,IFERROR(C_CALC!$B$67/A_INPUT!$B$108/12,0),0)) -> 15016.875 | H17: =K16 -> 0 | I17: =H17*A_INPUT!$B$105/12 -> 0 | J17: =IF(H17<=0,0,MIN(H17,C_CALC!$B$72-I17)) -> 0 | K17: =MAX(0,H17-J17) -> 0 | L17: =F17-G17-I17 -> 86761.352 | M17: =MAX(0,L17)*A_INPUT!$B$109 -> 17352.27 | N17: =L17-M17 -> 69409.082 | O17: =IF(A17=A_INPUT!$B$112*12,MAX(0,C_CALC!$B$66*(1-A17/12/A_INPUT!$B$107))+MAX(0,C_CALC!$B$67*(1-A17/12/A_INPUT!$B$108))+C_CALC!$B$68+A_INPUT!$B$50,0) -> 0 | P17: =F17-M17+O17 -> 84425.957 | Q17: =Q16+P17 -> -517740.43 | R17: =N17+G17-J17+O17 -> 84425.957 | S17: =1/(1+A_INPUT!$B$110/12)^A17 -> 0.92036217 | T17: =P17*S17 -> 77702.457 | U17: =U16+T17 -> -555179.96 | W17: =IF(AND(Q17>=0,Q16<0),A17,0) -> 0 | X17: =IF(AND(U17>=0,U16<0),A17,0) -> 0
A18: 11 | B18: =ROUNDUP(A18/12,0) -> 1 | C18: =IF(A18>A_INPUT!$B$112*12,0,C_CALC!$B$43*(1+A_INPUT!$B$111)^(B18-1)) -> 205630.85 | D18: =-C18*C_CALC!$B$57 -> -58852.625 | E18: =IF(A18>A_INPUT!$B$112*12,0,-((A_INPUT!$B$87-A_INPUT!$B$77)-IF(B18=1,F_SERVICE!$B$32,0)+A_INPUT!$B$77*(1+A_INPUT!$B$78)^(B18-1))) -> -45000 | F18: =C18+D18+E18 -> 101778.23 | G18: =IF(A18>A_INPUT!$B$112*12,0,IF(A18<=A_INPUT!$B$107*12,IFERROR(C_CALC!$B$66/A_INPUT!$B$107/12,0),0)+IF(A18<=A_INPUT!$B$108*12,IFERROR(C_CALC!$B$67/A_INPUT!$B$108/12,0),0)) -> 15016.875 | H18: =K17 -> 0 | I18: =H18*A_INPUT!$B$105/12 -> 0 | J18: =IF(H18<=0,0,MIN(H18,C_CALC!$B$72-I18)) -> 0 | K18: =MAX(0,H18-J18) -> 0 | L18: =F18-G18-I18 -> 86761.352 | M18: =MAX(0,L18)*A_INPUT!$B$109 -> 17352.27 | N18: =L18-M18 -> 69409.082 | O18: =IF(A18=A_INPUT!$B$112*12,MAX(0,C_CALC!$B$66*(1-A18/12/A_INPUT!$B$107))+MAX(0,C_CALC!$B$67*(1-A18/12/A_INPUT!$B$108))+C_CALC!$B$68+A_INPUT!$B$50,0) -> 0 | P18: =F18-M18+O18 -> 84425.957 | Q18: =Q17+P18 -> -433314.47 | R18: =N18+G18-J18+O18 -> 84425.957 | S18: =1/(1+A_INPUT!$B$110/12)^A18 -> 0.91275587 | T18: =P18*S18 -> 77060.287 | U18: =U17+T18 -> -478119.67 | W18: =IF(AND(Q18>=0,Q17<0),A18,0) -> 0 | X18: =IF(AND(U18>=0,U17<0),A18,0) -> 0
A19: 12 | B19: =ROUNDUP(A19/12,0) -> 1 | C19: =IF(A19>A_INPUT!$B$112*12,0,C_CALC!$B$43*(1+A_INPUT!$B$111)^(B19-1)) -> 205630.85 | D19: =-C19*C_CALC!$B$57 -> -58852.625 | E19: =IF(A19>A_INPUT!$B$112*12,0,-((A_INPUT!$B$87-A_INPUT!$B$77)-IF(B19=1,F_SERVICE!$B$32,0)+A_INPUT!$B$77*(1+A_INPUT!$B$78)^(B19-1))) -> -45000 | F19: =C19+D19+E19 -> 101778.23 | G19: =IF(A19>A_INPUT!$B$112*12,0,IF(A19<=A_INPUT!$B$107*12,IFERROR(C_CALC!$B$66/A_INPUT!$B$107/12,0),0)+IF(A19<=A_INPUT!$B$108*12,IFERROR(C_CALC!$B$67/A_INPUT!$B$108/12,0),0)) -> 15016.875 | H19: =K18 -> 0 | I19: =H19*A_INPUT!$B$105/12 -> 0 | J19: =IF(H19<=0,0,MIN(H19,C_CALC!$B$72-I19)) -> 0 | K19: =MAX(0,H19-J19) -> 0 | L19: =F19-G19-I19 -> 86761.352 | M19: =MAX(0,L19)*A_INPUT!$B$109 -> 17352.27 | N19: =L19-M19 -> 69409.082 | O19: =IF(A19=A_INPUT!$B$112*12,MAX(0,C_CALC!$B$66*(1-A19/12/A_INPUT!$B$107))+MAX(0,C_CALC!$B$67*(1-A19/12/A_INPUT!$B$108))+C_CALC!$B$68+A_INPUT!$B$50,0) -> 0 | P19: =F19-M19+O19 -> 84425.957 | Q19: =Q18+P19 -> -348888.52 | R19: =N19+G19-J19+O19 -> 84425.957 | S19: =1/(1+A_INPUT!$B$110/12)^A19 -> 0.90521243 | T19: =P19*S19 -> 76423.426 | U19: =U18+T19 -> -401696.24 | W19: =IF(AND(Q19>=0,Q18<0),A19,0) -> 0 | X19: =IF(AND(U19>=0,U18<0),A19,0) -> 0
... A67: 60 | B67: =ROUNDUP(A67/12,0) -> 5 | C67: =IF(A67>A_INPUT!$B$112*12,0,C_CALC!$B$43*(1+A_INPUT!$B$111)^(B67-1)) -> 249945.59 | D67: =-C67*C_CALC!$B$57 -> -71535.733 | E67: =IF(A67>A_INPUT!$B$112*12,0,-((A_INPUT!$B$87-A_INPUT!$B$77)-IF(B67=1,F_SERVICE!$B$32,0)+A_INPUT!$B$77*(1+A_INPUT!$B$78)^(B67-1))) -> -50970.99 | F67: =C67+D67+E67 -> 127438.86 | G67: =IF(A67>A_INPUT!$B$112*12,0,IF(A67<=A_INPUT!$B$107*12,IFERROR(C_CALC!$B$66/A_INPUT!$B$107/12,0),0)+IF(A67<=A_INPUT!$B$108*12,IFERROR(C_CALC!$B$67/A_INPUT!$B$108/12,0),0)) -> 15016.875 | H67: =K66 -> 0 | I67: =H67*A_INPUT!$B$105/12 -> 0 | J67: =IF(H67<=0,0,MIN(H67,C_CALC!$B$72-I67)) -> 0 | K67: =MAX(0,H67-J67) -> 0 | L67: =F67-G67-I67 -> 112421.99 | M67: =MAX(0,L67)*A_INPUT!$B$109 -> 22484.398 | N67: =L67-M67 -> 89937.591 | O67: =IF(A67=A_INPUT!$B$112*12,MAX(0,C_CALC!$B$66*(1-A67/12/A_INPUT!$B$107))+MAX(0,C_CALC!$B$67*(1-A67/12/A_INPUT!$B$108))+C_CALC!$B$68+A_INPUT!$B$50,0) -> 460987.5 | P67: =F67-M67+O67 -> 565941.97 | Q67: =Q66+P67 -> 4756645.2 | R67: =N67+G67-J67+O67 -> 565941.97 | S67: =1/(1+A_INPUT!$B$110/12)^A67 -> 0.60778859 | T67: =P67*S67 -> 343973.07 | U67: =U66+T67 -> 3308196.4 | W67: =IF(AND(Q67>=0,Q66<0),A67,0) -> 0 | X67: =IF(AND(U67>=0,U66<0),A67,0) -> 0

Sheet F_SERVICE
A1: F) WARRANTY, MAINTENANCE & SYSTEM FEE / ประกัน บำรุงรักษา และค่าบริการระบบ
A2: ที่มา: เอกสาร Samsung Commercial Franchise / ตารางสรุปราคาอุปกรณ์ (ก.ย. 2026) | ปีแรกทุกอย่างรวมอยู่ในราคาแพ็กเกจแล้ว — ชีตนี้คิดค่าใช้จ่ายตั้งแต่ปีที่ 2 เป็นต้นไป
A4: 1) สิ่งที่รวมอยู่ในแพ็กเกจแล้ว / Included in package
A5: ประกันเครื่องซัก-อบ | B5: =INDEX(B_PACKAGES!$D$19:$G$19,MATCH(A_INPUT!$B$25,B_PACKAGES!$D$12:$G$12,0)) -> 3 | D5: จาก B_PACKAGES | E5: ปี — สูงสุดในไทย ตามเงื่อนไขการใช้งานปกติ
A6: ประกันกล่องหยอดเหรียญ | B6: 1 | D6: Input | E6: ปี
A7: งานบำรุงรักษาที่รวมในปีแรก | B7: =INDEX(B_PACKAGES!$D$18:$G$18,MATCH(A_INPUT!$B$25,B_PACKAGES!$D$12:$G$12,0)) -> 2 | D7: จาก B_PACKAGES | E7: ครั้ง — S = 1 ครั้ง, M&L = 2 ครั้ง
A8: ระบบ I'M CONTROL + ค่าบริการ ฟรี | B8: =INDEX(B_PACKAGES!$D$20:$G$20,MATCH(A_INPUT!$B$25,B_PACKAGES!$D$12:$G$12,0)) -> 1 | D8: จาก B_PACKAGES | E8: ปี — รวมระบบจ่ายเงิน QR CODE และ QR API 1 บัญชี
A10: 2) ค่าบำรุงรักษาหลังปีแรก / Maintenance from year 2
A11: ค่าบำรุงรักษาต่อครั้ง (ทั้งร้าน) | B11: 3500 | D11: Input | E11: บาท/ครั้ง — ยังไม่ใช่ราคาทางการ ต้องยืนยันกับ Samsung
A12: จำนวนครั้งต่อปี | B12: 2 | D12: Input | E12: ครั้ง/ปี (เท่ากับที่แพ็กเกจ M&L ให้)
A13: ค่าบำรุงรักษาต่อปี | B13: =F_SERVICE!$B$11*F_SERVICE!$B$12 -> 7000 | D13: Formula | E13: บาท/ปี
A14: ค่าบำรุงรักษาเฉลี่ยต่อเดือน (ส่งไป A_INPUT) | B14: =F_SERVICE!$B$13/12 -> 583.33333 | D14: Formula | E14: บาท/เดือน
A16: 3) ค่าบริการระบบ I'M CONTROL หลังปีแรก — เปรียบเทียบ 2 ทางเลือก
A17: ทางเลือก A : เปิดใช้งานระบบสแกนชำระเงิน PromptPay 3%
A18: ค่าบริการรายเดือน/รายสาขา/รายปี | B18: 0 | D18: Formula | E18: ได้รับยกเว้นทั้งหมดทันทีเมื่อเปิดสแกน — ต้นทุนไปอยู่ที่ค่าธรรมเนียม 3% ของยอดสแกน (คิดในต้นทุนผันแปร)
A19: ทางเลือก B : ไม่เปิดสแกน (รับเหรียญ/แบงก์อย่างเดียว)
A20: ค่าบริการรายเดือน ต่อเครื่อง | B20: 100 | D20: Input | E20: บาท/เครื่อง/เดือน (1 Stack นับ 2 เครื่อง)
A21: ค่าบริการรายเดือน ต่อสาขา | B21: 700 | D21: Input | E21: บาท/สาขา/เดือน — เฉพาะสาขาที่มี 7 เครื่องขึ้นไป
A22: ค่าบริการรายปี | B22: 8000 | D22: Input | E22: บาท/ปี — ค่าดูแลรักษาและบำรุงรักษาระบบรายปี
A23: จำนวนเครื่องที่ระบบนับ | B23: =A_INPUT!$B$33 -> 10 | D23: จาก A_INPUT | E23: เครื่อง
A24: ค่าบริการระบบรวมต่อเดือน (ทางเลือก B) | B24: =F_SERVICE!$B$23*F_SERVICE!$B$20+IF(F_SERVICE!$B$23>=7,F_SERVICE!$B$21,0)+F_SERVICE!$B$22/12 -> 2366.6667 | D24: Formula | E24: บาท/เดือน
A25: ยอดสแกนที่ทำให้สองทางเลือกเท่ากัน | B25: =IFERROR(F_SERVICE!$B$24/A_INPUT!$B$98,0) -> 78888.889 | D25: Formula | E25: บาท/เดือน — ถ้ายอดที่ลูกค้าสแกนจริงสูงกว่านี้ ทางเลือก B (ไม่เปิดสแกน) จะถูกกว่าในแง่ค่าธรรมเนียม
A26: ยอดสแกนจริงต่อเดือน (ประมาณการ) | B26: =C_CALC!$B$43*A_INPUT!$B$99 -> 123378.51 | D26: จาก C_CALC | E26: รายได้รวม x %ที่ชำระผ่านสแกน (ลิงก์อัตโนมัติ)
A27: ค่าธรรมเนียม 3% ที่ต้องจ่าย (ทางเลือก A) | B27: =F_SERVICE!$B$26*A_INPUT!$B$98 -> 3701.3553 | D27: Formula | E27: บาท/เดือน
A28: คำแนะนำ / Recommendation | B28: =IF(F_SERVICE!$B$27>F_SERVICE!$B$24,"ทางเลือก B ถูกกว่า "&TEXT(F_SERVICE!$B$27-F_SERVICE!$B$24,"#,##0")&" บาท/เดือน — แต่ถ้าไม่เปิดสแกน ลูกค้าจ่ายได้เฉพาะเหรียญ/แบงก์ ซึ่งมักทำให้ยอดขายลดลงมากกว่าที่ประหยัดได้","ทางเลือก A (เปิดสแกน 3%) ถูกกว่า "&TEXT(F_SERVICE!$B$24-F_SERVICE!$B$27,"#,##0")&" บาท/เดือน และสะดวกกับลูกค้ามากกว่า") -> ทางเลือก B ถูกกว่า 1,335 บาท/เดือน — แต่ถ้าไม่เปิดสแกน ลูกค้าจ่ายได้เฉพาะเหรียญ/แบงก์ ซึ่งมักทำให้ยอดขายลดลงมากกว่าที่ประหยัดได้ | D28: Formula | E28: เทียบค่าธรรมเนียมจริงกับค่าบริการระบบรายเดือน
A29: ค่าบริการระบบที่ใช้จริง (ส่งไป A_INPUT) | B29: =IF(A_INPUT!$B$97="เปิดสแกน PromptPay 3% (ฟรีค่าบริการระบบ)",F_SERVICE!$B$18,F_SERVICE!$B$24) -> 0 | D29: Formula | E29: บาท/เดือน
A31: 4) SUMMARY / สรุป
A32: ส่วนลดปีแรก (รวมอยู่ในแพ็กเกจแล้ว) | B32: =F_SERVICE!$B$14+F_SERVICE!$B$29 -> 583.33333 | D32: Formula | E32: บาท/เดือน — ชีต E_CASHFLOW จะหักค่านี้ออกจากค่าใช้จ่ายคงที่ของปีที่ 1 ให้อัตโนมัติ
A33: ค่าบำรุงรักษา + ค่าบริการระบบ ต่อปี (ปีที่ 2 เป็นต้นไป) | B33: =(F_SERVICE!$B$14+F_SERVICE!$B$29)*12 -> 7000 | D33: Formula | E33: บาท/ปี
A34: หมายเหตุเพิ่มเติม
A35: • ค่าธรรมเนียมสแกน PromptPay 3% คิดเฉพาะยอดที่สแกนเท่านั้น ไม่เกี่ยวกับเงินสด — ตัดรอบ 7 วัน (จันทร์-อาทิตย์) โอนทุกวันพุธผ่าน K BIZ
A36: • ช่องทาง TrueMoney Payment คิดค่าธรรมเนียม 3.5% ต่อรายการ (เป็นตัวเลือกเสริม เปิด/ปิดได้)
A37: • การนับเครื่อง: เครื่องวางซ้อนบน-ล่าง 1 Stack ระบบนับเป็น 2 เครื่อง
A38: • หลังหมดประกัน 3 ปี ควรตั้งงบซ่อมเพิ่มที่ช่อง 'ค่าซ่อมผันแปร' ใน A_INPUT เป็น 2-3%

Sheet G_SCENARIO
A1: G) SCENARIO & SENSITIVITY / วิเคราะห์สถานการณ์และความอ่อนไหว
A3: 1) SCENARIO ANALYSIS / สถานการณ์จำลอง
A4: สถานการณ์ | B4: ตัวคูณลูกค้า | C4: ตัวคูณราคา | D4: ตัวคูณค่าเช่า | E4: รายได้/เดือน | F4: EBITDA/เดือน | G4: กำไรสุทธิ/เดือน | H4: คืนทุน (เดือน) | I4: ROI/ปี
A5: Worst / แย่ที่สุด | B5: 0.7 | C5: 0.9 | D5: 1.1 | E5: =(MIN(C_CALC!$B$27*$B5,C_CALC!$B$16)*C_CALC!$B$45*$C5+C_CALC!$B$41*$B5+C_CALC!$B$42) -> 133033.23 | F5: =((MIN(C_CALC!$B$27*$B5,C_CALC!$B$16)*C_CALC!$B$45*$C5+C_CALC!$B$41*$B5+C_CALC!$B$42)*(1-C_CALC!$B$57)-(A_INPUT!$B$87+A_INPUT!$B$77*($D5-1))) -> 46875.093 | G5: =((((MIN(C_CALC!$B$27*$B5,C_CALC!$B$16)*C_CALC!$B$45*$C5+C_CALC!$B$41*$B5+C_CALC!$B$42)*(1-C_CALC!$B$57)-(A_INPUT!$B$87+A_INPUT!$B$77*($D5-1)))-C_CALC!$B$79-C_CALC!$B$81)-MAX(0,(((MIN(C_CALC!$B$27*$B5,C_CALC!$B$16)*C_CALC!$B$45*$C5+C_CALC!$B$41*$B5+C_CALC!$B$42)*(1-C_CALC!$B$57)-(A_INPUT!$B$87+A_INPUT!$B$77*($D5-1)))-C_CALC!$B$79-C_CALC!$B$81))*A_INPUT!$B$109) -> 25486.574 | H5: =IFERROR(IF(G5+C_CALC!$B$79<=0,999,C_CALC!$B$69/(G5+C_CALC!$B$79)),999) -> 33.626766 | I5: =IFERROR(G5*12/C_CALC!$B$69,0) -> 0.22455131
A6: Base / ฐาน | B6: 1 | C6: 1 | D6: 1 | E6: =(MIN(C_CALC!$B$27*$B6,C_CALC!$B$16)*C_CALC!$B$45*$C6+C_CALC!$B$41*$B6+C_CALC!$B$42) -> 205630.85 | F6: =((MIN(C_CALC!$B$27*$B6,C_CALC!$B$16)*C_CALC!$B$45*$C6+C_CALC!$B$41*$B6+C_CALC!$B$42)*(1-C_CALC!$B$57)-(A_INPUT!$B$87+A_INPUT!$B$77*($D6-1))) -> 101194.89 | G6: =((((MIN(C_CALC!$B$27*$B6,C_CALC!$B$16)*C_CALC!$B$45*$C6+C_CALC!$B$41*$B6+C_CALC!$B$42)*(1-C_CALC!$B$57)-(A_INPUT!$B$87+A_INPUT!$B$77*($D6-1)))-C_CALC!$B$79-C_CALC!$B$81)-MAX(0,(((MIN(C_CALC!$B$27*$B6,C_CALC!$B$16)*C_CALC!$B$45*$C6+C_CALC!$B$41*$B6+C_CALC!$B$42)*(1-C_CALC!$B$57)-(A_INPUT!$B$87+A_INPUT!$B$77*($D6-1)))-C_CALC!$B$79-C_CALC!$B$81))*A_INPUT!$B$109) -> 68942.415 | H6: =IFERROR(IF(G6+C_CALC!$B$79<=0,999,C_CALC!$B$69/(G6+C_CALC!$B$79)),999) -> 16.222148 | I6: =IFERROR(G6*12/C_CALC!$B$69,0) -> 0.60742216
A7: Best / ดีที่สุด | B7: 1.3 | C7: 1.1 | D7: 1 | E7: =(MIN(C_CALC!$B$27*$B7,C_CALC!$B$16)*C_CALC!$B$45*$C7+C_CALC!$B$41*$B7+C_CALC!$B$42) -> 226994.06 | F7: =((MIN(C_CALC!$B$27*$B7,C_CALC!$B$16)*C_CALC!$B$45*$C7+C_CALC!$B$41*$B7+C_CALC!$B$42)*(1-C_CALC!$B$57)-(A_INPUT!$B$87+A_INPUT!$B$77*($D7-1))) -> 116443.84 | G7: =((((MIN(C_CALC!$B$27*$B7,C_CALC!$B$16)*C_CALC!$B$45*$C7+C_CALC!$B$41*$B7+C_CALC!$B$42)*(1-C_CALC!$B$57)-(A_INPUT!$B$87+A_INPUT!$B$77*($D7-1)))-C_CALC!$B$79-C_CALC!$B$81)-MAX(0,(((MIN(C_CALC!$B$27*$B7,C_CALC!$B$16)*C_CALC!$B$45*$C7+C_CALC!$B$41*$B7+C_CALC!$B$42)*(1-C_CALC!$B$57)-(A_INPUT!$B$87+A_INPUT!$B$77*($D7-1)))-C_CALC!$B$79-C_CALC!$B$81))*A_INPUT!$B$109) -> 81141.571 | H7: =IFERROR(IF(G7+C_CALC!$B$79<=0,999,C_CALC!$B$69/(G7+C_CALC!$B$79)),999) -> 14.164122 | I7: =IFERROR(G7*12/C_CALC!$B$69,0) -> 0.71490371
A9: ตัวคูณ 100% = ค่าฐานจาก A_INPUT | Worst = ลูกค้าเหลือ 70% ราคาลด 10% ค่าเช่าขึ้น 10%
A11: 2) SENSITIVITY — ระยะคืนทุน (เดือน) / Payback months
A12: ราคา \ % ลูกค้าที่ใช้บริการ | B12: 0.2 | C12: 0.25 | D12: 0.3 | E12: 0.35 | F12: 0.4 | G12: 0.45 | H12: 0.5
A13: 0.8 | B13: =IFERROR(IF(((((MIN(C_CALC!$B$27*(B$12/A_INPUT!$B$14),C_CALC!$B$16)*C_CALC!$B$45*$A13+C_CALC!$B$41*(B$12/A_INPUT!$B$14)+C_CALC!$B$42)*(1-C_CALC!$B$57)-(A_INPUT!$B$87+A_INPUT!$B$77*(1-1)))-C_CALC!$B$79-C_CALC!$B$81)-MAX(0,(((MIN(C_CALC!$B$27*(B$12/A_INPUT!$B$14),C_CALC!$B$16)*C_CALC!$B$45*$A13+C_CALC!$B$41*(B$12/A_INPUT!$B$14)+C_CALC!$B$42)*(1-C_CALC!$B$57)-(A_INPUT!$B$87+A_INPUT!$B$77*(1-1)))-C_CALC!$B$79-C_CALC!$B$81))*A_INPUT!$B$109)+C_CALC!$B$79<=0,999,C_CALC!$B$69/(((((MIN(C_CALC!$B$27*(B$12/A_INPUT!$B$14),C_CALC!$B$16)*C_CALC!$B$45*$A13+C_CALC!$B$41*(B$12/A_INPUT!$B$14)+C_CALC!$B$42)*(1-C_CALC!$B$57)-(A_INPUT!$B$87+A_INPUT!$B$77*(1-1)))-C_CALC!$B$79-C_CALC!$B$81)-MAX(0,(((MIN(C_CALC!$B$27*(B$12/A_INPUT!$B$14),C_CALC!$B$16)*C_CALC!$B$45*$A13+C_CALC!$B$41*(B$12/A_INPUT!$B$14)+C_CALC!$B$42)*(1-C_CALC!$B$57)-(A_INPUT!$B$87+A_INPUT!$B$77*(1-1)))-C_CALC!$B$79-C_CALC!$B$81))*A_INPUT!$B$109)+C_CALC!$B$79)),999) -> 62.462699 | C13: =IFERROR(IF(((((MIN(C_CALC!$B$27*(C$12/A_INPUT!$B$14),C_CALC!$B$16)*C_CALC!$B$45*$A13+C_CALC!$B$41*(C$12/A_INPUT!$B$14)+C_CALC!$B$42)*(1-C_CALC!$B$57)-(A_INPUT!$B$87+A_INPUT!$B$77*(1-1)))-C_CALC!$B$79-C_CALC!$B$81)-MAX(0,(((MIN(C_CALC!$B$27*(C$12/A_INPUT!$B$14),C_CALC!$B$16)*C_CALC!$B$45*$A13+C_CALC!$B$41*(C$12/A_INPUT!$B$14)+C_CALC!$B$42)*(1-C_CALC!$B$57)-(A_INPUT!$B$87+A_INPUT!$B$77*(1-1)))-C_CALC!$B$79-C_CALC!$B$81))*A_INPUT!$B$109)+C_CALC!$B$79<=0,999,C_CALC!$B$69/(((((MIN(C_CALC!$B$27*(C$12/A_INPUT!$B$14),C_CALC!$B$16)*C_CALC!$B$45*$A13+C_CALC!$B$41*(C$12/A_INPUT!$B$14)+C_CALC!$B$42)*(1-C_CALC!$B$57)-(A_INPUT!$B$87+A_INPUT!$B$77*(1-1)))-C_CALC!$B$79-C_CALC!$B$81)-MAX(0,(((MIN(C_CALC!$B$27*(C$12/A_INPUT!$B$14),C_CALC!$B$16)*C_CALC!$B$45*$A13+C_CALC!$B$41*(C$12/A_INPUT!$B$14)+C_CALC!$B$42)*(1-C_CALC!$B$57)-(A_INPUT!$B$87+A_INPUT!$B$77*(1-1)))-C_CALC!$B$79-C_CALC!$B$81))*A_INPUT!$B$109)+C_CALC!$B$79)),999) -> 38.234702 | D13: =IFERROR(IF(((((MIN(C_CALC!$B$27*(D$12/A_INPUT!$B$14),C_CALC!$B$16)*C_CALC!$B$45*$A13+C_CALC!$B$41*(D$12/A_INPUT!$B$14)+C_CALC!$B$42)*(1-C_CALC!$B$57)-(A_INPUT!$B$87+A_INPUT!$B$77*(1-1)))-C_CALC!$B$79-C_CALC!$B$81)-MAX(0,(((MIN(C_CALC!$B$27*(D$12/A_INPUT!$B$14),C_CALC!$B$16)*C_CALC!$B$45*$A13+C_CALC!$B$41*(D$12/A_INPUT!$B$14)+C_CALC!$B$42)*(1-C_CALC!$B$57)-(A_INPUT!$B$87+A_INPUT!$B$77*(1-1)))-C_CALC!$B$79-C_CALC!$B$81))*A_INPUT!$B$109)+C_CALC!$B$79<=0,999,C_CALC!$B$69/(((((MIN(C_CALC!$B$27*(D$12/A_INPUT!$B$14),C_CALC!$B$16)*C_CALC!$B$45*$A13+C_CALC!$B$41*(D$12/A_INPUT!$B$14)+C_CALC!$B$42)*(1-C_CALC!$B$57)-(A_INPUT!$B$87+A_INPUT!$B$77*(1-1)))-C_CALC!$B$79-C_CALC!$B$81)-MAX(0,(((MIN(C_CALC!$B$27*(D$12/A_INPUT!$B$14),C_CALC!$B$16)*C_CALC!$B$45*$A13+C_CALC!$B$41*(D$12/A_INPUT!$B$14)+C_CALC!$B$42)*(1-C_CALC!$B$57)-(A_INPUT!$B$87+A_INPUT!$B$77*(1-1)))-C_CALC!$B$79-C_CALC!$B$81))*A_INPUT!$B$109)+C_CALC!$B$79)),999) -> 27.549008 | E13: =IFERROR(IF(((((MIN(C_CALC!$B$27*(E$12/A_INPUT!$B$14),C_CALC!$B$16)*C_CALC!$B$45*$A13+C_CALC!$B$41*(E$12/A_INPUT!$B$14)+C_CALC!$B$42)*(1-C_CALC!$B$57)-(A_INPUT!$B$87+A_INPUT!$B$77*(1-1)))-C_CALC!$B$79-C_CALC!$B$81)-MAX(0,(((MIN(C_CALC!$B$27*(E$12/A_INPUT!$B$14),C_CALC!$B$16)*C_CALC!$B$45*$A13+C_CALC!$B$41*(E$12/A_INPUT!$B$14)+C_CALC!$B$42)*(1-C_CALC!$B$57)-(A_INPUT!$B$87+A_INPUT!$B$77*(1-1)))-C_CALC!$B$79-C_CALC!$B$81))*A_INPUT!$B$109)+C_CALC!$B$79<=0,999,C_CALC!$B$69/(((((MIN(C_CALC!$B$27*(E$12/A_INPUT!$B$14),C_CALC!$B$16)*C_CALC!$B$45*$A13+C_CALC!$B$41*(E$12/A_INPUT!$B$14)+C_CALC!$B$42)*(1-C_CALC!$B$57)-(A_INPUT!$B$87+A_INPUT!$B$77*(1-1)))-C_CALC!$B$79-C_CALC!$B$81)-MAX(0,(((MIN(C_CALC!$B$27*(E$12/A_INPUT!$B$14),C_CALC!$B$16)*C_CALC!$B$45*$A13+C_CALC!$B$41*(E$12/A_INPUT!$B$14)+C_CALC!$B$42)*(1-C_CALC!$B$57)-(A_INPUT!$B$87+A_INPUT!$B$77*(1-1)))-C_CALC!$B$79-C_CALC!$B$81))*A_INPUT!$B$109)+C_CALC!$B$79)),999) -> 22.352907 | F13: =IFERROR(IF(((((MIN(C_CALC!$B$27*(F$12/A_INPUT!$B$14),C_CALC!$B$16)*C_CALC!$B$45*$A13+C_CALC!$B$41*(F$12/A_INPUT!$B$14)+C_CALC!$B$42)*(1-C_CALC!$B$57)-(A_INPUT!$B$87+A_INPUT!$B$77*(1-1)))-C_CALC!$B$79-C_CALC!$B$81)-MAX(0,(((MIN(C_CALC!$B$27*(F$12/A_INPUT!$B$14),C_CALC!$B$16)*C_CALC!$B$45*$A13+C_CALC!$B$41*(F$12/A_INPUT!$B$14)+C_CALC!$B$42)*(1-C_CALC!$B$57)-(A_INPUT!$B$87+A_INPUT!$B$77*(1-1)))-C_CALC!$B$79-C_CALC!$B$81))*A_INPUT!$B$109)+C_CALC!$B$79<=0,999,C_CALC!$B$69/(((((MIN(C_CALC!$B$27*(F$12/A_INPUT!$B$14),C_CALC!$B$16)*C_CALC!$B$45*$A13+C_CALC!$B$41*(F$12/A_INPUT!$B$14)+C_CALC!$B$42)*(1-C_CALC!$B$57)-(A_INPUT!$B$87+A_INPUT!$B$77*(1-1)))-C_CALC!$B$79-C_CALC!$B$81)-MAX(0,(((MIN(C_CALC!$B$27*(F$12/A_INPUT!$B$14),C_CALC!$B$16)*C_CALC!$B$45*$A13+C_CALC!$B$41*(F$12/A_INPUT!$B$14)+C_CALC!$B$42)*(1-C_CALC!$B$57)-(A_INPUT!$B$87+A_INPUT!$B$77*(1-1)))-C_CALC!$B$79-C_CALC!$B$81))*A_INPUT!$B$109)+C_CALC!$B$79)),999) -> 22.233821 | G13: =IFERROR(IF(((((MIN(C_CALC!$B$27*(G$12/A_INPUT!$B$14),C_CALC!$B$16)*C_CALC!$B$45*$A13+C_CALC!$B$41*(G$12/A_INPUT!$B$14)+C_CALC!$B$42)*(1-C_CALC!$B$57)-(A_INPUT!$B$87+A_INPUT!$B$77*(1-1)))-C_CALC!$B$79-C_CALC!$B$81)-MAX(0,(((MIN(C_CALC!$B$27*(G$12/A_INPUT!$B$14),C_CALC!$B$16)*C_CALC!$B$45*$A13+C_CALC!$B$41*(G$12/A_INPUT!$B$14)+C_CALC!$B$42)*(1-C_CALC!$B$57)-(A_INPUT!$B$87+A_INPUT!$B$77*(1-1)))-C_CALC!$B$79-C_CALC!$B$81))*A_INPUT!$B$109)+C_CALC!$B$79<=0,999,C_CALC!$B$69/(((((MIN(C_CALC!$B$27*(G$12/A_INPUT!$B$14),C_CALC!$B$16)*C_CALC!$B$45*$A13+C_CALC!$B$41*(G$12/A_INPUT!$B$14)+C_CALC!$B$42)*(1-C_CALC!$B$57)-(A_INPUT!$B$87+A_INPUT!$B$77*(1-1)))-C_CALC!$B$79-C_CALC!$B$81)-MAX(0,(((MIN(C_CALC!$B$27*(G$12/A_INPUT!$B$14),C_CALC!$B$16)*C_CALC!$B$45*$A13+C_CALC!$B$41*(G$12/A_INPUT!$B$14)+C_CALC!$B$42)*(1-C_CALC!$B$57)-(A_INPUT!$B$87+A_INPUT!$B$77*(1-1)))-C_CALC!$B$79-C_CALC!$B$81))*A_INPUT!$B$109)+C_CALC!$B$79)),999) -> 22.115997 | H13: =IFERROR(IF(((((MIN(C_CALC!$B$27*(H$12/A_INPUT!$B$14),C_CALC!$B$16)*C_CALC!$B$45*$A13+C_CALC!$B$41*(H$12/A_INPUT!$B$14)+C_CALC!$B$42)*(1-C_CALC!$B$57)-(A_INPUT!$B$87+A_INPUT!$B$77*(1-1)))-C_CALC!$B$79-C_CALC!$B$81)-MAX(0,(((MIN(C_CALC!$B$27*(H$12/A_INPUT!$B$14),C_CALC!$B$16)*C_CALC!$B$45*$A13+C_CALC!$B$41*(H$12/A_INPUT!$B$14)+C_CALC!$B$42)*(1-C_CALC!$B$57)-(A_INPUT!$B$87+A_INPUT!$B$77*(1-1)))-C_CALC!$B$79-C_CALC!$B$81))*A_INPUT!$B$109)+C_CALC!$B$79<=0,999,C_CALC!$B$69/(((((MIN(C_CALC!$B$27*(H$12/A_INPUT!$B$14),C_CALC!$B$16)*C_CALC!$B$45*$A13+C_CALC!$B$41*(H$12/A_INPUT!$B$14)+C_CALC!$B$42)*(1-C_CALC!$B$57)-(A_INPUT!$B$87+A_INPUT!$B$77*(1-1)))-C_CALC!$B$79-C_CALC!$B$81)-MAX(0,(((MIN(C_CALC!$B$27*(H$12/A_INPUT!$B$14),C_CALC!$B$16)*C_CALC!$B$45*$A13+C_CALC!$B$41*(H$12/A_INPUT!$B$14)+C_CALC!$B$42)*(1-C_CALC!$B$57)-(A_INPUT!$B$87+A_INPUT!$B$77*(1-1)))-C_CALC!$B$79-C_CALC!$B$81))*A_INPUT!$B$109)+C_CALC!$B$79)),999) -> 21.999415
